Workbook

Sheet PARTNERS SUMMARY
G1: SEPT 5G Router (ODU) Leads | O1: OCT 5G Router (ODU) Leads | X1: NOV 5G Router (ODU) Leads | AJ1: ENTERPRISE PARTNERS CONVERTED LEADS DOD
A2: EBB PARTNERS FWA LEADS SUMMARY | G2: =SUBTOTAL(9,G4:G1048571) -> 42 | H2: =SUBTOTAL(9,H4:H1048571) -> 25 | I2: =SUBTOTAL(9,I4:I1048571) -> 12 | J2: =SUBTOTAL(9,J4:J1048571) -> 2 | K2: =SUBTOTAL(9,K4:K1048571) -> 3 | L2: =SUBTOTAL(9,L4:L1048571) -> 16 | M2: =IFERROR(L2/G2,0) -> 0.38095238 | O2: =SUBTOTAL(9,O4:O1048571) -> 808 | P2: =SUBTOTAL(9,P4:P1048571) -> 7 | Q2: =SUBTOTAL(9,Q4:Q1048571) -> 513 | R2: =SUBTOTAL(9,R4:R1048571) -> 184 | S2: =SUBTOTAL(9,S4:S1048571) -> 98 | T2: =SUBTOTAL(9,T4:T1048571) -> 6 | U2: =SUBTOTAL(9,U4:U1048571) -> 335 | V2: =IFERROR(U2/O2,0) -> 0.41460396 | X2: =SUBTOTAL(9,X4:X1048571) -> 1269 | Y2: =SUBTOTAL(9,Y4:Y1048571) -> 2 | Z2: =SUBTOTAL(9,Z4:Z1048571) -> 285 | AA2: =SUBTOTAL(9,AA4:AA1048571) -> 107 | AB2: =SUBTOTAL(9,AB4:AB1048571) -> 11 | AC2: =SUBTOTAL(9,AC4:AC1048571) -> 0 | AD2: =SUBTOTAL(9,AD4:AD1048571) -> 613 | AE2: Nov | AF2: =IFERROR(AD2/X2,0) -> 0.48305753 | AH2: =SUM(AH4:AH157) -> 0 | AI2: =SUM(AI4:AI157) -> 0 | AJ2: =SUM(AJ4:AJ157) -> 0 | AK2: =SUM(AK4:AK157) -> 0 | AL2: =SUM(AL4:AL157) -> 0 | AM2: =SUM(AM4:AM157) -> 0 | AN2: =SUM(AN4:AN157) -> 0 | AO2: =SUM(AO4:AO157) -> 0 | ... DI2: =SUM(DI4:DI157) -> 23 | DJ2: =SUBTOTAL(9,DJ4:DJ1048576) -> 34 | DK2: =SUBTOTAL(9,DK4:DK1048576) -> 21 | DL2: =SUBTOTAL(9,DL4:DL1048576) -> 31 | DM2: =SUBTOTAL(9,DM4:DM1048576) -> 24 | DN2: =SUBTOTAL(9,DN4:DN1048576) -> 23 | DO2: =SUBTOTAL(9,DO4:DO1048576) -> 30 | DP2: =SUBTOTAL(9,DP4:DP1048576) -> 0 | DQ2: =SUBTOTAL(9,DQ4:DQ1048576) -> 0 | ... EY2: =SUBTOTAL(9,EY4:EY1048576) -> 0
A3: PAE | B3: Partners Name | C3: KYC_ID | D3: EMAIL ID | E3: Zone | F3: REGION | G3: Leads | H3: Confirmed | I3: Rejected | J3: Unreachable | K3: Postponed(Update W) | L3: Converted/waiting conversion | M3: Conv. Rate (%) | O3: Leads | P3: Prospect | Q3: Confirmed | R3: Rejected | S3: Unreachable | T3: Postponed(Update W) | U3: Converted/waiting conversion | V3: Conv. Rate (%) | X3: Leads | Y3: Prospect | Z3: Confirmed | AA3: Rejected | AB3: Unreachable | AC3: Postponed(Update W) | AD3: Converted/waiting conversion | AE3: Wrongly Leads MTD | AF3: Conv. Rate (%) | AH3: 45901 | AI3: 45902 | AJ3: 45903 | AK3: 45904 | AL3: 45905 | AM3: 45906 | AN3: 45907 | AO3: 45908 | AP3: 45909 | AQ3: 45910 | AR3: 45911 | AS3: 45912 | AT3: 45913 | AU3: 45914 | AV3: 45915 | AW3: 45916 | AX3: 45917 | AY3: 45918 | AZ3: 45919 | BA3: 45920 | BB3: 45921 | BC3: 45922 | BD3: 45923 | BE3: 45924 | BF3: 45925 | BG3: 45926 | BH3: 45927 | BI3: 45928 | BJ3: 45929 | BK3: 45930 | BL3: 45931 | BM3: 45932 | BN3: 45933 | BO3: 45934 | BP3: 45935 | BQ3: 45936 | BR3: 45937 | BS3: 45938 | BT3: 45939 | BU3: 45940 | BV3: 45941 | BW3: 45942 | BX3: 45943 | BY3: 45944 | BZ3: 45945 | CA3: 45946 | CB3: 45947 | CC3: 45948 | CD3: 45949 | CE3: 45950 | CF3: 45951 | CG3: 45952 | CH3: 45953 | CI3: 45954 | CJ3: 45955 | CK3: 45956 | CL3: 45957 | CM3: 45958 | CN3: 45959 | CO3: 45960 | CP3: 45961 | CQ3: 45962 | CR3: 45963 | CS3: 45964 | CT3: 45965 | CU3: 45966 | CV3: 45967 | CW3: 45968 | CX3: 45969 | CY3: 45970 | CZ3: 45971 | DA3: 45972 | DB3: 45973 | DC3: 45974 | DD3: 45975 | DE3: 45976 | DF3: 45977 | DG3: 45978 | DH3: 45979 | DI3: 45980 | DJ3: 45981 | DK3: 45982 | DL3: 45983 | DM3: 45984 | DN3: 45985 | DO3: 45986 | DP3: 45987 | DQ3: 45988 | DR3: 45989 | DS3: 45990 | DT3: 45991 | DU3: 45992 | DV3: 45993 | DW3: 45994 | DX3: 45995 | DY3: 45996 | DZ3: 45997 | EA3: 45998 | EB3: 45999 | EC3: 46000 | ED3: 46001 | EE3: 46002 | EF3: 46003 | EG3: 46004 | EH3: 46005 | EI3: 46006 | EJ3: 46007 | EK3: 46008 | EL3: 46009 | EM3: 46010 | EN3: 46011 | EO3: 46012 | EP3: 46013 | EQ3: 46014 | ER3: 46015 | ES3: 46016 | ET3: 46017 | EU3: 46018 | EV3: 46019 | EW3: 46020 | EX3: 46021 | EY3: 46022
A4: Mariana Hongo | B4: STRATON AND CRAPHT LIMITED | C4: 751785175 | D4: Warierowycliffe@gmail.com | E4: Kisumu | F4: Western | G4: =COUNTIF('SEPT DUMP '!$C:$C,'PARTNERS SUMMARY'!$B4) -> 12 | H4: =COUNTIFS('SEPT DUMP '!$C:$C,'PARTNERS SUMMARY'!$B4,'SEPT DUMP '!$O:$O,"Confirmed") -> 9 | I4: =COUNTIFS('SEPT DUMP '!$C:$C,'PARTNERS SUMMARY'!$B4,'SEPT DUMP '!$O:$O,"Rejected") -> 3 | J4: =COUNTIFS('SEPT DUMP '!$C:$C,'PARTNERS SUMMARY'!$B4,'SEPT DUMP '!$O:$O,"Unreachable") -> 0 | K4: =COUNTIFS('SEPT DUMP '!$C:$C,'PARTNERS SUMMARY'!$B4,'SEPT DUMP '!$O:$O,"Postponed(Update Y)") -> 0 | L4: =SUM(AH4:BK4) -> 3 | M4: =IFERROR(L4/G4,0) -> 0.25 | O4: =COUNTIF('OCT DUMP'!$D:$D,'PARTNERS SUMMARY'!$B4) -> 306 | P4: =COUNTIFS('OCT DUMP'!$D:$D,'PARTNERS SUMMARY'!$B4,'OCT DUMP'!Q:Q,"Prospect") -> 0 | Q4: =COUNTIFS('OCT DUMP'!$D:$D,'PARTNERS SUMMARY'!$B4,'OCT DUMP'!$Q:$Q,"Confirmed") -> 184 | R4: =COUNTIFS('OCT DUMP'!$D:$D,'PARTNERS SUMMARY'!$B4,'OCT DUMP'!$Q:$Q,"Rejected") -> 83 | S4: =COUNTIFS('OCT DUMP'!$D:$D,'PARTNERS SUMMARY'!$B4,'OCT DUMP'!$Q:$Q,"Unreachable") -> 39 | T4: =COUNTIFS('OCT DUMP'!$D:$D,'PARTNERS SUMMARY'!$B4,'OCT DUMP'!$Q:$Q,"Postponed(Update Y)") -> 0 | U4: =SUM(BL4:CP4) -> 159 | V4: =IFERROR(U4/O4,0) -> 0.51960784 | X4: =COUNTIF('NOV DUMP'!C:C,'PARTNERS SUMMARY'!$B4) -> 199 | Y4: =COUNTIFS('NOV DUMP'!$C:$C,'PARTNERS SUMMARY'!$B4,'NOV DUMP'!$S:$S,"Prospect") -> 0 | Z4: =COUNTIFS('NOV DUMP'!$C:$C,'PARTNERS SUMMARY'!$B4,'NOV DUMP'!$S:$S,"Confirmed") -> 50 | AA4: =COUNTIFS('NOV DUMP'!$C:$C,'PARTNERS SUMMARY'!$B4,'NOV DUMP'!$S:$S,"Rejected") -> 16 | AB4: =COUNTIFS('NOV DUMP'!$C:$C,'PARTNERS SUMMARY'!$B4,'NOV DUMP'!$S:$S,"Unreachable") -> 0 | AC4: =COUNTIFS('NOV DUMP'!$C:$C,'PARTNERS SUMMARY'!$B4,'NOV DUMP'!$S:$S,"Postponed(Update Y)") -> 0 | AD4: =SUM(CQ4:DT4) -> 164 | AE4: =COUNTIFS('ACTIVATED LEADS '!$H:$H,'PARTNERS SUMMARY'!$B4,'ACTIVATED LEADS '!$K:$K,'PARTNERS SUMMARY'!$AE$2,'ACTIVATED LEADS '!$C:$C,"16") -> 99 | AF4: =IFERROR(AD4/X4,0) -> 0.8241206 | AH4: =COUNTIFS('ACTIVATED LEADS '!$H:$H,$B4,'ACTIVATED LEADS '!$D:$D,'PARTNERS SUMMARY'!AH$3) -> 0 | AI4: =COUNTIFS('ACTIVATED LEADS '!$H:$H,$B4,'ACTIVATED LEADS '!$D:$D,'PARTNERS SUMMARY'!AI$3) -> 0 | AJ4: =COUNTIFS('ACTIVATED LEADS '!$H:$H,$B4,'ACTIVATED LEADS '!$D:$D,'PARTNERS SUMMARY'!AJ$3) -> 0 | AK4: =COUNTIFS('ACTIVATED LEADS '!$H:$H,$B4,'ACTIVATED LEADS '!$D:$D,'PARTNERS SUMMARY'!AK$3) -> 0 | AL4: =COUNTIFS('ACTIVATED LEADS '!$H:$H,$B4,'ACTIVATED LEADS '!$D:$D,'PARTNERS SUMMARY'!AL$3) -> 0 | AM4: =COUNTIFS('ACTIVATED LEADS '!$H:$H,$B4,'ACTIVATED LEADS '!$D:$D,'PARTNERS SUMMARY'!AM$3) -> 0 | AN4: =COUNTIFS('ACTIVATED LEADS '!$H:$H,$B4,'ACTIVATED LEADS '!$D:$D,'PARTNERS SUMMARY'!AN$3) -> 0 | AO4: =COUNTIFS('ACTIVATED LEADS '!$H:$H,$B4,'ACTIVATED LEADS '!$D:$D,'PARTNERS SUMMARY'!AO$3) -> 0 | ... DO4: =COUNTIFS('ACTIVATED LEADS '!$H:$H,$B4,'ACTIVATED LEADS '!$D:$D,'PARTNERS SUMMARY'!DO$3) -> 2
A5: Brian Odero | B5: SYLVERENE COMMUNICATION | C5: 735820631 | D5: Wanderaclinton2@gmail.com | E5: two rivers | F5: Nairobi | G5: =COUNTIF('SEPT DUMP '!$C:$C,'PARTNERS SUMMARY'!$B5) -> 6 | H5: =COUNTIFS('SEPT DUMP '!$C:$C,'PARTNERS SUMMARY'!$B5,'SEPT DUMP '!$O:$O,"Confirmed") -> 2 | I5: =COUNTIFS('SEPT DUMP '!$C:$C,'PARTNERS SUMMARY'!$B5,'SEPT DUMP '!$O:$O,"Rejected") -> 3 | J5: =COUNTIFS('SEPT DUMP '!$C:$C,'PARTNERS SUMMARY'!$B5,'SEPT DUMP '!$O:$O,"Unreachable") -> 1 | K5: =COUNTIFS('SEPT DUMP '!$C:$C,'PARTNERS SUMMARY'!$B5,'SEPT DUMP '!$O:$O,"Postponed(Update Y)") -> 0 | L5: =SUM(AH5:BK5) -> 2 | M5: =IFERROR(L5/G5,0) -> 0.33333333 | O5: =COUNTIF('OCT DUMP'!$D:$D,'PARTNERS SUMMARY'!$B5) -> 172 | P5: =COUNTIFS('OCT DUMP'!$D:$D,'PARTNERS SUMMARY'!$B5,'OCT DUMP'!Q:Q,"Prospect") -> 1 | Q5: =COUNTIFS('OCT DUMP'!$D:$D,'PARTNERS SUMMARY'!$B5,'OCT DUMP'!$Q:$Q,"Confirmed") -> 108 | R5: =COUNTIFS('OCT DUMP'!$D:$D,'PARTNERS SUMMARY'!$B5,'OCT DUMP'!$Q:$Q,"Rejected") -> 43 | S5: =COUNTIFS('OCT DUMP'!$D:$D,'PARTNERS SUMMARY'!$B5,'OCT DUMP'!$Q:$Q,"Unreachable") -> 19 | T5: =COUNTIFS('OCT DUMP'!$D:$D,'PARTNERS SUMMARY'!$B5,'OCT DUMP'!$Q:$Q,"Postponed(Update Y)") -> 1 | U5: =SUM(BL5:CP5) -> 44 | V5: =IFERROR(U5/O5,0) -> 0.25581395 | X5: =COUNTIF('NOV DUMP'!C:C,'PARTNERS SUMMARY'!$B5) -> 275 | Y5: =COUNTIFS('NOV DUMP'!$C:$C,'PARTNERS SUMMARY'!$B5,'NOV DUMP'!$S:$S,"Prospect") -> 0 | Z5: =COUNTIFS('NOV DUMP'!$C:$C,'PARTNERS SUMMARY'!$B5,'NOV DUMP'!$S:$S,"Confirmed") -> 58 | AA5: =COUNTIFS('NOV DUMP'!$C:$C,'PARTNERS SUMMARY'!$B5,'NOV DUMP'!$S:$S,"Rejected") -> 34 | AB5: =COUNTIFS('NOV DUMP'!$C:$C,'PARTNERS SUMMARY'!$B5,'NOV DUMP'!$S:$S,"Unreachable") -> 2 | AC5: =COUNTIFS('NOV DUMP'!$C:$C,'PARTNERS SUMMARY'!$B5,'NOV DUMP'!$S:$S,"Postponed(Update Y)") -> 0 | AD5: =SUM(CQ5:DT5) -> 113 | AE5: =COUNTIFS('ACTIVATED LEADS '!$H:$H,'PARTNERS SUMMARY'!$B5,'ACTIVATED LEADS '!$K:$K,'PARTNERS SUMMARY'!$AE$2,'ACTIVATED LEADS '!$C:$C,"16") -> 81 | AF5: =IFERROR(AD5/X5,0) -> 0.41090909 | AH5: =COUNTIFS('ACTIVATED LEADS '!$H:$H,$B5,'ACTIVATED LEADS '!$D:$D,'PARTNERS SUMMARY'!AH$3) -> 0 | AI5: =COUNTIFS('ACTIVATED LEADS '!$H:$H,$B5,'ACTIVATED LEADS '!$D:$D,'PARTNERS SUMMARY'!AI$3) -> 0 | AJ5: =COUNTIFS('ACTIVATED LEADS '!$H:$H,$B5,'ACTIVATED LEADS '!$D:$D,'PARTNERS SUMMARY'!AJ$3) -> 0 | AK5: =COUNTIFS('ACTIVATED LEADS '!$H:$H,$B5,'ACTIVATED LEADS '!$D:$D,'PARTNERS SUMMARY'!AK$3) -> 0 | AL5: =COUNTIFS('ACTIVATED LEADS '!$H:$H,$B5,'ACTIVATED LEADS '!$D:$D,'PARTNERS SUMMARY'!AL$3) -> 0 | AM5: =COUNTIFS('ACTIVATED LEADS '!$H:$H,$B5,'ACTIVATED LEADS '!$D:$D,'PARTNERS SUMMARY'!AM$3) -> 0 | AN5: =COUNTIFS('ACTIVATED LEADS '!$H:$H,$B5,'ACTIVATED LEADS '!$D:$D,'PARTNERS SUMMARY'!AN$3) -> 0 | AO5: =COUNTIFS('ACTIVATED LEADS '!$H:$H,$B5,'ACTIVATED LEADS '!$D:$D,'PARTNERS SUMMARY'!AO$3) -> 0 | ... DO5: =COUNTIFS('ACTIVATED LEADS '!$H:$H,$B5,'ACTIVATED LEADS '!$D:$D,'PARTNERS SUMMARY'!DO$3) -> 3
A6: Mariana Hongo | B6: DAVIJO DISTRIBUTORS | C6: 781446693 | D6: beatriceokinyi9@gmail.com | E6: Kisumu | F6: Western | G6: =COUNTIF('SEPT DUMP '!$C:$C,'PARTNERS SUMMARY'!$B6) -> 13 | H6: =COUNTIFS('SEPT DUMP '!$C:$C,'PARTNERS SUMMARY'!$B6,'SEPT DUMP '!$O:$O,"Confirmed") -> 6 | I6: =COUNTIFS('SEPT DUMP '!$C:$C,'PARTNERS SUMMARY'!$B6,'SEPT DUMP '!$O:$O,"Rejected") -> 4 | J6: =COUNTIFS('SEPT DUMP '!$C:$C,'PARTNERS SUMMARY'!$B6,'SEPT DUMP '!$O:$O,"Unreachable") -> 1 | K6: =COUNTIFS('SEPT DUMP '!$C:$C,'PARTNERS SUMMARY'!$B6,'SEPT DUMP '!$O:$O,"Postponed(Update Y)") -> 2 | L6: =SUM(AH6:BK6) -> 5 | M6: =IFERROR(L6/G6,0) -> 0.38461538 | O6: =COUNTIF('OCT DUMP'!$D:$D,'PARTNERS SUMMARY'!$B6) -> 26 | P6: =COUNTIFS('OCT DUMP'!$D:$D,'PARTNERS SUMMARY'!$B6,'OCT DUMP'!Q:Q,"Prospect") -> 0 | Q6: =COUNTIFS('OCT DUMP'!$D:$D,'PARTNERS SUMMARY'!$B6,'OCT DUMP'!$Q:$Q,"Confirmed") -> 14 | R6: =COUNTIFS('OCT DUMP'!$D:$D,'PARTNERS SUMMARY'!$B6,'OCT DUMP'!$Q:$Q,"Rejected") -> 8 | S6: =COUNTIFS('OCT DUMP'!$D:$D,'PARTNERS SUMMARY'!$B6,'OCT DUMP'!$Q:$Q,"Unreachable") -> 3 | T6: =COUNTIFS('OCT DUMP'!$D:$D,'PARTNERS SUMMARY'!$B6,'OCT DUMP'!$Q:$Q,"Postponed(Update Y)") -> 1 | U6: =SUM(BL6:CP6) -> 9 | V6: =IFERROR(U6/O6,0) -> 0.34615385 | X6: =COUNTIF('NOV DUMP'!C:C,'PARTNERS SUMMARY'!$B6) -> 35 | Y6: =COUNTIFS('NOV DUMP'!$C:$C,'PARTNERS SUMMARY'!$B6,'NOV DUMP'!$S:$S,"Prospect") -> 0 | Z6: =COUNTIFS('NOV DUMP'!$C:$C,'PARTNERS SUMMARY'!$B6,'NOV DUMP'!$S:$S,"Confirmed") -> 9 | AA6: =COUNTIFS('NOV DUMP'!$C:$C,'PARTNERS SUMMARY'!$B6,'NOV DUMP'!$S:$S,"Rejected") -> 1 | AB6: =COUNTIFS('NOV DUMP'!$C:$C,'PARTNERS SUMMARY'!$B6,'NOV DUMP'!$S:$S,"Unreachable") -> 0 | AC6: =COUNTIFS('NOV DUMP'!$C:$C,'PARTNERS SUMMARY'!$B6,'NOV DUMP'!$S:$S,"Postponed(Update Y)") -> 0 | AD6: =SUM(CQ6:DT6) -> 20 | AE6: =COUNTIFS('ACTIVATED LEADS '!$H:$H,'PARTNERS SUMMARY'!$B6,'ACTIVATED LEADS '!$K:$K,'PARTNERS SUMMARY'!$AE$2,'ACTIVATED LEADS '!$C:$C,"16") -> 6 | AF6: =IFERROR(AD6/X6,0) -> 0.57142857 | AH6: =COUNTIFS('ACTIVATED LEADS '!$H:$H,$B6,'ACTIVATED LEADS '!$D:$D,'PARTNERS SUMMARY'!AH$3) -> 0 | AI6: =COUNTIFS('ACTIVATED LEADS '!$H:$H,$B6,'ACTIVATED LEADS '!$D:$D,'PARTNERS SUMMARY'!AI$3) -> 0 | AJ6: =COUNTIFS('ACTIVATED LEADS '!$H:$H,$B6,'ACTIVATED LEADS '!$D:$D,'PARTNERS SUMMARY'!AJ$3) -> 0 | AK6: =COUNTIFS('ACTIVATED LEADS '!$H:$H,$B6,'ACTIVATED LEADS '!$D:$D,'PARTNERS SUMMARY'!AK$3) -> 0 | AL6: =COUNTIFS('ACTIVATED LEADS '!$H:$H,$B6,'ACTIVATED LEADS '!$D:$D,'PARTNERS SUMMARY'!AL$3) -> 0 | AM6: =COUNTIFS('ACTIVATED LEADS '!$H:$H,$B6,'ACTIVATED LEADS '!$D:$D,'PARTNERS SUMMARY'!AM$3) -> 0 | AN6: =COUNTIFS('ACTIVATED LEADS '!$H:$H,$B6,'ACTIVATED LEADS '!$D:$D,'PARTNERS SUMMARY'!AN$3) -> 0 | AO6: =COUNTIFS('ACTIVATED LEADS '!$H:$H,$B6,'ACTIVATED LEADS '!$D:$D,'PARTNERS SUMMARY'!AO$3) -> 0 | ... DO6: =COUNTIFS('ACTIVATED LEADS '!$H:$H,$B6,'ACTIVATED LEADS '!$D:$D,'PARTNERS SUMMARY'!DO$3) -> 2
A7: Brian Odero | B7: DENTECH INNOVATIONS | C7: 107373669 | D7: geoffreywasikeh@gmail.com | E7: Nairobi | F7: Nairobi | G7: =COUNTIF('SEPT DUMP '!$C:$C,'PARTNERS SUMMARY'!$B7) -> 2 | H7: =COUNTIFS('SEPT DUMP '!$C:$C,'PARTNERS SUMMARY'!$B7,'SEPT DUMP '!$O:$O,"Confirmed") -> 1 | I7: =COUNTIFS('SEPT DUMP '!$C:$C,'PARTNERS SUMMARY'!$B7,'SEPT DUMP '!$O:$O,"Rejected") -> 1 | J7: =COUNTIFS('SEPT DUMP '!$C:$C,'PARTNERS SUMMARY'!$B7,'SEPT DUMP '!$O:$O,"Unreachable") -> 0 | K7: =COUNTIFS('SEPT DUMP '!$C:$C,'PARTNERS SUMMARY'!$B7,'SEPT DUMP '!$O:$O,"Postponed(Update Y)") -> 0 | L7: =SUM(AH7:BK7) -> 1 | M7: =IFERROR(L7/G7,0) -> 0.5 | O7: =COUNTIF('OCT DUMP'!$D:$D,'PARTNERS SUMMARY'!$B7) -> 17 | P7: =COUNTIFS('OCT DUMP'!$D:$D,'PARTNERS SUMMARY'!$B7,'OCT DUMP'!Q:Q,"Prospect") -> 0 | Q7: =COUNTIFS('OCT DUMP'!$D:$D,'PARTNERS SUMMARY'!$B7,'OCT DUMP'!$Q:$Q,"Confirmed") -> 14 | R7: =COUNTIFS('OCT DUMP'!$D:$D,'PARTNERS SUMMARY'!$B7,'OCT DUMP'!$Q:$Q,"Rejected") -> 2 | S7: =COUNTIFS('OCT DUMP'!$D:$D,'PARTNERS SUMMARY'!$B7,'OCT DUMP'!$Q:$Q,"Unreachable") -> 1 | T7: =COUNTIFS('OCT DUMP'!$D:$D,'PARTNERS SUMMARY'!$B7,'OCT DUMP'!$Q:$Q,"Postponed(Update Y)") -> 0 | U7: =SUM(BL7:CP7) -> 15 | V7: =IFERROR(U7/O7,0) -> 0.88235294 | X7: =COUNTIF('NOV DUMP'!C:C,'PARTNERS SUMMARY'!$B7) -> 16 | Y7: =COUNTIFS('NOV DUMP'!$C:$C,'PARTNERS SUMMARY'!$B7,'NOV DUMP'!$S:$S,"Prospect") -> 0 | Z7: =COUNTIFS('NOV DUMP'!$C:$C,'PARTNERS SUMMARY'!$B7,'NOV DUMP'!$S:$S,"Confirmed") -> 2 | AA7: =COUNTIFS('NOV DUMP'!$C:$C,'PARTNERS SUMMARY'!$B7,'NOV DUMP'!$S:$S,"Rejected") -> 1 | AB7: =COUNTIFS('NOV DUMP'!$C:$C,'PARTNERS SUMMARY'!$B7,'NOV DUMP'!$S:$S,"Unreachable") -> 0 | AC7: =COUNTIFS('NOV DUMP'!$C:$C,'PARTNERS SUMMARY'!$B7,'NOV DUMP'!$S:$S,"Postponed(Update Y)") -> 0 | AD7: =SUM(CQ7:DT7) -> 16 | AE7: =COUNTIFS('ACTIVATED LEADS '!$H:$H,'PARTNERS SUMMARY'!$B7,'ACTIVATED LEADS '!$K:$K,'PARTNERS SUMMARY'!$AE$2,'ACTIVATED LEADS '!$C:$C,"16") -> 9 | AF7: =IFERROR(AD7/X7,0) -> 1 | AH7: =COUNTIFS('ACTIVATED LEADS '!$H:$H,$B7,'ACTIVATED LEADS '!$D:$D,'PARTNERS SUMMARY'!AH$3) -> 0 | AI7: =COUNTIFS('ACTIVATED LEADS '!$H:$H,$B7,'ACTIVATED LEADS '!$D:$D,'PARTNERS SUMMARY'!AI$3) -> 0 | AJ7: =COUNTIFS('ACTIVATED LEADS '!$H:$H,$B7,'ACTIVATED LEADS '!$D:$D,'PARTNERS SUMMARY'!AJ$3) -> 0 | AK7: =COUNTIFS('ACTIVATED LEADS '!$H:$H,$B7,'ACTIVATED LEADS '!$D:$D,'PARTNERS SUMMARY'!AK$3) -> 0 | AL7: =COUNTIFS('ACTIVATED LEADS '!$H:$H,$B7,'ACTIVATED LEADS '!$D:$D,'PARTNERS SUMMARY'!AL$3) -> 0 | AM7: =COUNTIFS('ACTIVATED LEADS '!$H:$H,$B7,'ACTIVATED LEADS '!$D:$D,'PARTNERS SUMMARY'!AM$3) -> 0 | AN7: =COUNTIFS('ACTIVATED LEADS '!$H:$H,$B7,'ACTIVATED LEADS '!$D:$D,'PARTNERS SUMMARY'!AN$3) -> 0 | AO7: =COUNTIFS('ACTIVATED LEADS '!$H:$H,$B7,'ACTIVATED LEADS '!$D:$D,'PARTNERS SUMMARY'!AO$3) -> 0 | ... DO7: =COUNTIFS('ACTIVATED LEADS '!$H:$H,$B7,'ACTIVATED LEADS '!$D:$D,'PARTNERS SUMMARY'!DO$3) -> 2
A8: Mariana Hongo | B8: RYDEME EAST AFRICA LTD | C8: 788338738 | D8: Kenombette@gmail.com | E8: Kisii | F8: Western | G8: =COUNTIF('SEPT DUMP '!$C:$C,'PARTNERS SUMMARY'!$B8) -> 1 | H8: =COUNTIFS('SEPT DUMP '!$C:$C,'PARTNERS SUMMARY'!$B8,'SEPT DUMP '!$O:$O,"Confirmed") -> 1 | I8: =COUNTIFS('SEPT DUMP '!$C:$C,'PARTNERS SUMMARY'!$B8,'SEPT DUMP '!$O:$O,"Rejected") -> 0 | J8: =COUNTIFS('SEPT DUMP '!$C:$C,'PARTNERS SUMMARY'!$B8,'SEPT DUMP '!$O:$O,"Unreachable") -> 0 | K8: =COUNTIFS('SEPT DUMP '!$C:$C,'PARTNERS SUMMARY'!$B8,'SEPT DUMP '!$O:$O,"Postponed(Update Y)") -> 0 | L8: =SUM(AH8:BK8) -> 1 | M8: =IFERROR(L8/G8,0) -> 1 | O8: =COUNTIF('OCT DUMP'!$D:$D,'PARTNERS SUMMARY'!$B8) -> 7 | P8: =COUNTIFS('OCT DUMP'!$D:$D,'PARTNERS SUMMARY'!$B8,'OCT DUMP'!Q:Q,"Prospect") -> 0 | Q8: =COUNTIFS('OCT DUMP'!$D:$D,'PARTNERS SUMMARY'!$B8,'OCT DUMP'!$Q:$Q,"Confirmed") -> 4 | R8: =COUNTIFS('OCT DUMP'!$D:$D,'PARTNERS SUMMARY'!$B8,'OCT DUMP'!$Q:$Q,"Rejected") -> 3 | S8: =COUNTIFS('OCT DUMP'!$D:$D,'PARTNERS SUMMARY'!$B8,'OCT DUMP'!$Q:$Q,"Unreachable") -> 0 | T8: =COUNTIFS('OCT DUMP'!$D:$D,'PARTNERS SUMMARY'!$B8,'OCT DUMP'!$Q:$Q,"Postponed(Update Y)") -> 0 | U8: =SUM(BL8:CP8) -> 8 | V8: =IFERROR(U8/O8,0) -> 1.1428571 | X8: =COUNTIF('NOV DUMP'!C:C,'PARTNERS SUMMARY'!$B8) -> 18 | Y8: =COUNTIFS('NOV DUMP'!$C:$C,'PARTNERS SUMMARY'!$B8,'NOV DUMP'!$S:$S,"Prospect") -> 0 | Z8: =COUNTIFS('NOV DUMP'!$C:$C,'PARTNERS SUMMARY'!$B8,'NOV DUMP'!$S:$S,"Confirmed") -> 8 | AA8: =COUNTIFS('NOV DUMP'!$C:$C,'PARTNERS SUMMARY'!$B8,'NOV DUMP'!$S:$S,"Rejected") -> 0 | AB8: =COUNTIFS('NOV DUMP'!$C:$C,'PARTNERS SUMMARY'!$B8,'NOV DUMP'!$S:$S,"Unreachable") -> 0 | AC8: =COUNTIFS('NOV DUMP'!$C:$C,'PARTNERS SUMMARY'!$B8,'NOV DUMP'!$S:$S,"Postponed(Update Y)") -> 0 | AD8: =SUM(CQ8:DT8) -> 13 | AE8: =COUNTIFS('ACTIVATED LEADS '!$H:$H,'PARTNERS SUMMARY'!$B8,'ACTIVATED LEADS '!$K:$K,'PARTNERS SUMMARY'!$AE$2,'ACTIVATED LEADS '!$C:$C,"16") -> 13 | AF8: =IFERROR(AD8/X8,0) -> 0.72222222 | AH8: =COUNTIFS('ACTIVATED LEADS '!$H:$H,$B8,'ACTIVATED LEADS '!$D:$D,'PARTNERS SUMMARY'!AH$3) -> 0 | AI8: =COUNTIFS('ACTIVATED LEADS '!$H:$H,$B8,'ACTIVATED LEADS '!$D:$D,'PARTNERS SUMMARY'!AI$3) -> 0 | AJ8: =COUNTIFS('ACTIVATED LEADS '!$H:$H,$B8,'ACTIVATED LEADS '!$D:$D,'PARTNERS SUMMARY'!AJ$3) -> 0 | AK8: =COUNTIFS('ACTIVATED LEADS '!$H:$H,$B8,'ACTIVATED LEADS '!$D:$D,'PARTNERS SUMMARY'!AK$3) -> 0 | AL8: =COUNTIFS('ACTIVATED LEADS '!$H:$H,$B8,'ACTIVATED LEADS '!$D:$D,'PARTNERS SUMMARY'!AL$3) -> 0 | AM8: =COUNTIFS('ACTIVATED LEADS '!$H:$H,$B8,'ACTIVATED LEADS '!$D:$D,'PARTNERS SUMMARY'!AM$3) -> 0 | AN8: =COUNTIFS('ACTIVATED LEADS '!$H:$H,$B8,'ACTIVATED LEADS '!$D:$D,'PARTNERS SUMMARY'!AN$3) -> 0 | AO8: =COUNTIFS('ACTIVATED LEADS '!$H:$H,$B8,'ACTIVATED LEADS '!$D:$D,'PARTNERS SUMMARY'!AO$3) -> 0 | ... DO8: =COUNTIFS('ACTIVATED LEADS '!$H:$H,$B8,'ACTIVATED LEADS '!$D:$D,'PARTNERS SUMMARY'!DO$3) -> 0
A9: Mariana Hongo | B9: DULO INVESTMENTS | C9: 735153617 | D9: Wuodjasega4@gmail.com | E9: Kisumu | F9: Western | G9: =COUNTIF('SEPT DUMP '!$C:$C,'PARTNERS SUMMARY'!$B9) -> 5 | H9: =COUNTIFS('SEPT DUMP '!$C:$C,'PARTNERS SUMMARY'!$B9,'SEPT DUMP '!$O:$O,"Confirmed") -> 4 | I9: =COUNTIFS('SEPT DUMP '!$C:$C,'PARTNERS SUMMARY'!$B9,'SEPT DUMP '!$O:$O,"Rejected") -> 1 | J9: =COUNTIFS('SEPT DUMP '!$C:$C,'PARTNERS SUMMARY'!$B9,'SEPT DUMP '!$O:$O,"Unreachable") -> 0 | K9: =COUNTIFS('SEPT DUMP '!$C:$C,'PARTNERS SUMMARY'!$B9,'SEPT DUMP '!$O:$O,"Postponed(Update Y)") -> 0 | L9: =SUM(AH9:BK9) -> 3 | M9: =IFERROR(L9/G9,0) -> 0.6 | O9: =COUNTIF('OCT DUMP'!$D:$D,'PARTNERS SUMMARY'!$B9) -> 42 | P9: =COUNTIFS('OCT DUMP'!$D:$D,'PARTNERS SUMMARY'!$B9,'OCT DUMP'!Q:Q,"Prospect") -> 0 | Q9: =COUNTIFS('OCT DUMP'!$D:$D,'PARTNERS SUMMARY'!$B9,'OCT DUMP'!$Q:$Q,"Confirmed") -> 29 | R9: =COUNTIFS('OCT DUMP'!$D:$D,'PARTNERS SUMMARY'!$B9,'OCT DUMP'!$Q:$Q,"Rejected") -> 6 | S9: =COUNTIFS('OCT DUMP'!$D:$D,'PARTNERS SUMMARY'!$B9,'OCT DUMP'!$Q:$Q,"Unreachable") -> 7 | T9: =COUNTIFS('OCT DUMP'!$D:$D,'PARTNERS SUMMARY'!$B9,'OCT DUMP'!$Q:$Q,"Postponed(Update Y)") -> 0 | U9: =SUM(BL9:CP9) -> 27 | V9: =IFERROR(U9/O9,0) -> 0.64285714 | X9: =COUNTIF('NOV DUMP'!C:C,'PARTNERS SUMMARY'!$B9) -> 42 | Y9: =COUNTIFS('NOV DUMP'!$C:$C,'PARTNERS SUMMARY'!$B9,'NOV DUMP'!$S:$S,"Prospect") -> 0 | Z9: =COUNTIFS('NOV DUMP'!$C:$C,'PARTNERS SUMMARY'!$B9,'NOV DUMP'!$S:$S,"Confirmed") -> 12 | AA9: =COUNTIFS('NOV DUMP'!$C:$C,'PARTNERS SUMMARY'!$B9,'NOV DUMP'!$S:$S,"Rejected") -> 9 | AB9: =COUNTIFS('NOV DUMP'!$C:$C,'PARTNERS SUMMARY'!$B9,'NOV DUMP'!$S:$S,"Unreachable") -> 2 | AC9: =COUNTIFS('NOV DUMP'!$C:$C,'PARTNERS SUMMARY'!$B9,'NOV DUMP'!$S:$S,"Postponed(Update Y)") -> 0 | AD9: =SUM(CQ9:DT9) -> 20 | AE9: =COUNTIFS('ACTIVATED LEADS '!$H:$H,'PARTNERS SUMMARY'!$B9,'ACTIVATED LEADS '!$K:$K,'PARTNERS SUMMARY'!$AE$2,'ACTIVATED LEADS '!$C:$C,"16") -> 4 | AF9: =IFERROR(AD9/X9,0) -> 0.47619048 | AH9: =COUNTIFS('ACTIVATED LEADS '!$H:$H,$B9,'ACTIVATED LEADS '!$D:$D,'PARTNERS SUMMARY'!AH$3) -> 0 | AI9: =COUNTIFS('ACTIVATED LEADS '!$H:$H,$B9,'ACTIVATED LEADS '!$D:$D,'PARTNERS SUMMARY'!AI$3) -> 0 | AJ9: =COUNTIFS('ACTIVATED LEADS '!$H:$H,$B9,'ACTIVATED LEADS '!$D:$D,'PARTNERS SUMMARY'!AJ$3) -> 0 | AK9: =COUNTIFS('ACTIVATED LEADS '!$H:$H,$B9,'ACTIVATED LEADS '!$D:$D,'PARTNERS SUMMARY'!AK$3) -> 0 | AL9: =COUNTIFS('ACTIVATED LEADS '!$H:$H,$B9,'ACTIVATED LEADS '!$D:$D,'PARTNERS SUMMARY'!AL$3) -> 0 | AM9: =COUNTIFS('ACTIVATED LEADS '!$H:$H,$B9,'ACTIVATED LEADS '!$D:$D,'PARTNERS SUMMARY'!AM$3) -> 0 | AN9: =COUNTIFS('ACTIVATED LEADS '!$H:$H,$B9,'ACTIVATED LEADS '!$D:$D,'PARTNERS SUMMARY'!AN$3) -> 0 | AO9: =COUNTIFS('ACTIVATED LEADS '!$H:$H,$B9,'ACTIVATED LEADS '!$D:$D,'PARTNERS SUMMARY'!AO$3) -> 0 | ... DO9: =COUNTIFS('ACTIVATED LEADS '!$H:$H,$B9,'ACTIVATED LEADS '!$D:$D,'PARTNERS SUMMARY'!DO$3) -> 2
A10: Fiona Maiyo | B10: LUHYA LUO DOLLAR CONNECTION | C10: 100866403 | D10: modizoali@gmail.com | E10: Eldoret | F10: Rift | G10: =COUNTIF('SEPT DUMP '!$C:$C,'PARTNERS SUMMARY'!$B10) -> 0 | H10: =COUNTIFS('SEPT DUMP '!$C:$C,'PARTNERS SUMMARY'!$B10,'SEPT DUMP '!$O:$O,"Confirmed") -> 0 | I10: =COUNTIFS('SEPT DUMP '!$C:$C,'PARTNERS SUMMARY'!$B10,'SEPT DUMP '!$O:$O,"Rejected") -> 0 | J10: =COUNTIFS('SEPT DUMP '!$C:$C,'PARTNERS SUMMARY'!$B10,'SEPT DUMP '!$O:$O,"Unreachable") -> 0 | K10: =COUNTIFS('SEPT DUMP '!$C:$C,'PARTNERS SUMMARY'!$B10,'SEPT DUMP '!$O:$O,"Postponed(Update Y)") -> 0 | L10: =SUM(AH10:BK10) -> 0 | M10: =IFERROR(L10/G10,0) -> 0 | O10: =COUNTIF('OCT DUMP'!$D:$D,'PARTNERS SUMMARY'!$B10) -> 49 | P10: =COUNTIFS('OCT DUMP'!$D:$D,'PARTNERS SUMMARY'!$B10,'OCT DUMP'!Q:Q,"Prospect") -> 0 | Q10: =COUNTIFS('OCT DUMP'!$D:$D,'PARTNERS SUMMARY'!$B10,'OCT DUMP'!$Q:$Q,"Confirmed") -> 37 | R10: =COUNTIFS('OCT DUMP'!$D:$D,'PARTNERS SUMMARY'!$B10,'OCT DUMP'!$Q:$Q,"Rejected") -> 6 | S10: =COUNTIFS('OCT DUMP'!$D:$D,'PARTNERS SUMMARY'!$B10,'OCT DUMP'!$Q:$Q,"Unreachable") -> 6 | T10: =COUNTIFS('OCT DUMP'!$D:$D,'PARTNERS SUMMARY'!$B10,'OCT DUMP'!$Q:$Q,"Postponed(Update Y)") -> 0 | U10: =SUM(BL10:CP10) -> 21 | V10: =IFERROR(U10/O10,0) -> 0.42857143 | X10: =COUNTIF('NOV DUMP'!C:C,'PARTNERS SUMMARY'!$B10) -> 75 | Y10: =COUNTIFS('NOV DUMP'!$C:$C,'PARTNERS SUMMARY'!$B10,'NOV DUMP'!$S:$S,"Prospect") -> 1 | Z10: =COUNTIFS('NOV DUMP'!$C:$C,'PARTNERS SUMMARY'!$B10,'NOV DUMP'!$S:$S,"Confirmed") -> 16 | AA10: =COUNTIFS('NOV DUMP'!$C:$C,'PARTNERS SUMMARY'!$B10,'NOV DUMP'!$S:$S,"Rejected") -> 3 | AB10: =COUNTIFS('NOV DUMP'!$C:$C,'PARTNERS SUMMARY'!$B10,'NOV DUMP'!$S:$S,"Unreachable") -> 0 | AC10: =COUNTIFS('NOV DUMP'!$C:$C,'PARTNERS SUMMARY'!$B10,'NOV DUMP'!$S:$S,"Postponed(Update Y)") -> 0 | AD10: =SUM(CQ10:DT10) -> 47 | AE10: =COUNTIFS('ACTIVATED LEADS '!$H:$H,'PARTNERS SUMMARY'!$B10,'ACTIVATED LEADS '!$K:$K,'PARTNERS SUMMARY'!$AE$2,'ACTIVATED LEADS '!$C:$C,"16") -> 46 | AF10: =IFERROR(AD10/X10,0) -> 0.62666667 | AH10: =COUNTIFS('ACTIVATED LEADS '!$H:$H,$B10,'ACTIVATED LEADS '!$D:$D,'PARTNERS SUMMARY'!AH$3) -> 0 | AI10: =COUNTIFS('ACTIVATED LEADS '!$H:$H,$B10,'ACTIVATED LEADS '!$D:$D,'PARTNERS SUMMARY'!AI$3) -> 0 | AJ10: =COUNTIFS('ACTIVATED LEADS '!$H:$H,$B10,'ACTIVATED LEADS '!$D:$D,'PARTNERS SUMMARY'!AJ$3) -> 0 | AK10: =COUNTIFS('ACTIVATED LEADS '!$H:$H,$B10,'ACTIVATED LEADS '!$D:$D,'PARTNERS SUMMARY'!AK$3) -> 0 | AL10: =COUNTIFS('ACTIVATED LEADS '!$H:$H,$B10,'ACTIVATED LEADS '!$D:$D,'PARTNERS SUMMARY'!AL$3) -> 0 | AM10: =COUNTIFS('ACTIVATED LEADS '!$H:$H,$B10,'ACTIVATED LEADS '!$D:$D,'PARTNERS SUMMARY'!AM$3) -> 0 | AN10: =COUNTIFS('ACTIVATED LEADS '!$H:$H,$B10,'ACTIVATED LEADS '!$D:$D,'PARTNERS SUMMARY'!AN$3) -> 0 | AO10: =COUNTIFS('ACTIVATED LEADS '!$H:$H,$B10,'ACTIVATED LEADS '!$D:$D,'PARTNERS SUMMARY'!AO$3) -> 0 | ... DO10: =COUNTIFS('ACTIVATED LEADS '!$H:$H,$B10,'ACTIVATED LEADS '!$D:$D,'PARTNERS SUMMARY'!DO$3) -> 0
A11: Brian Odero | B11: WEZESHA MTANDAO MASHINANI | C11: 103505274 | D11: everlyn.ameyo@gmail.com | E11: Runda | F11: Nairobi | G11: =COUNTIF('SEPT DUMP '!$C:$C,'PARTNERS SUMMARY'!$B11) -> 0 | H11: =COUNTIFS('SEPT DUMP '!$C:$C,'PARTNERS SUMMARY'!$B11,'SEPT DUMP '!$O:$O,"Confirmed") -> 0 | I11: =COUNTIFS('SEPT DUMP '!$C:$C,'PARTNERS SUMMARY'!$B11,'SEPT DUMP '!$O:$O,"Rejected") -> 0 | J11: =COUNTIFS('SEPT DUMP '!$C:$C,'PARTNERS SUMMARY'!$B11,'SEPT DUMP '!$O:$O,"Unreachable") -> 0 | K11: =COUNTIFS('SEPT DUMP '!$C:$C,'PARTNERS SUMMARY'!$B11,'SEPT DUMP '!$O:$O,"Postponed(Update Y)") -> 0 | L11: =SUM(AH11:BK11) -> 0 | M11: =IFERROR(L11/G11,0) -> 0 | O11: =COUNTIF('OCT DUMP'!$D:$D,'PARTNERS SUMMARY'!$B11) -> 3 | P11: =COUNTIFS('OCT DUMP'!$D:$D,'PARTNERS SUMMARY'!$B11,'OCT DUMP'!Q:Q,"Prospect") -> 0 | Q11: =COUNTIFS('OCT DUMP'!$D:$D,'PARTNERS SUMMARY'!$B11,'OCT DUMP'!$Q:$Q,"Confirmed") -> 2 | R11: =COUNTIFS('OCT DUMP'!$D:$D,'PARTNERS SUMMARY'!$B11,'OCT DUMP'!$Q:$Q,"Rejected") -> 0 | S11: =COUNTIFS('OCT DUMP'!$D:$D,'PARTNERS SUMMARY'!$B11,'OCT DUMP'!$Q:$Q,"Unreachable") -> 1 | T11: =COUNTIFS('OCT DUMP'!$D:$D,'PARTNERS SUMMARY'!$B11,'OCT DUMP'!$Q:$Q,"Postponed(Update Y)") -> 0 | U11: =SUM(BL11:CP11) -> 1 | V11: =IFERROR(U11/O11,0) -> 0.33333333 | X11: =COUNTIF('NOV DUMP'!C:C,'PARTNERS SUMMARY'!$B11) -> 0 | Y11: =COUNTIFS('NOV DUMP'!$C:$C,'PARTNERS SUMMARY'!$B11,'NOV DUMP'!$S:$S,"Prospect") -> 0 | Z11: =COUNTIFS('NOV DUMP'!$C:$C,'PARTNERS SUMMARY'!$B11,'NOV DUMP'!$S:$S,"Confirmed") -> 0 | AA11: =COUNTIFS('NOV DUMP'!$C:$C,'PARTNERS SUMMARY'!$B11,'NOV DUMP'!$S:$S,"Rejected") -> 0 | AB11: =COUNTIFS('NOV DUMP'!$C:$C,'PARTNERS SUMMARY'!$B11,'NOV DUMP'!$S:$S,"Unreachable") -> 0 | AC11: =COUNTIFS('NOV DUMP'!$C:$C,'PARTNERS SUMMARY'!$B11,'NOV DUMP'!$S:$S,"Postponed(Update Y)") -> 0 | AD11: =SUM(CQ11:DT11) -> 0 | AE11: =COUNTIFS('ACTIVATED LEADS '!$H:$H,'PARTNERS SUMMARY'!$B11,'ACTIVATED LEADS '!$K:$K,'PARTNERS SUMMARY'!$AE$2,'ACTIVATED LEADS '!$C:$C,"16") -> 0 | AF11: =IFERROR(AD11/X11,0) -> 0 | AH11: =COUNTIFS('ACTIVATED LEADS '!$H:$H,$B11,'ACTIVATED LEADS '!$D:$D,'PARTNERS SUMMARY'!AH$3) -> 0 | AI11: =COUNTIFS('ACTIVATED LEADS '!$H:$H,$B11,'ACTIVATED LEADS '!$D:$D,'PARTNERS SUMMARY'!AI$3) -> 0 | AJ11: =COUNTIFS('ACTIVATED LEADS '!$H:$H,$B11,'ACTIVATED LEADS '!$D:$D,'PARTNERS SUMMARY'!AJ$3) -> 0 | AK11: =COUNTIFS('ACTIVATED LEADS '!$H:$H,$B11,'ACTIVATED LEADS '!$D:$D,'PARTNERS SUMMARY'!AK$3) -> 0 | AL11: =COUNTIFS('ACTIVATED LEADS '!$H:$H,$B11,'ACTIVATED LEADS '!$D:$D,'PARTNERS SUMMARY'!AL$3) -> 0 | AM11: =COUNTIFS('ACTIVATED LEADS '!$H:$H,$B11,'ACTIVATED LEADS '!$D:$D,'PARTNERS SUMMARY'!AM$3) -> 0 | AN11: =COUNTIFS('ACTIVATED LEADS '!$H:$H,$B11,'ACTIVATED LEADS '!$D:$D,'PARTNERS SUMMARY'!AN$3) -> 0 | AO11: =COUNTIFS('ACTIVATED LEADS '!$H:$H,$B11,'ACTIVATED LEADS '!$D:$D,'PARTNERS SUMMARY'!AO$3) -> 0 | ... DO11: =COUNTIFS('ACTIVATED LEADS '!$H:$H,$B11,'ACTIVATED LEADS '!$D:$D,'PARTNERS SUMMARY'!DO$3) -> 0
A12: Brian Odero | B12: MANYA FIRM | C12: 108499681 | D12: Pishmouti@gmail.com | E12: Mulolongo | F12: Nairobi | G12: =COUNTIF('SEPT DUMP '!$C:$C,'PARTNERS SUMMARY'!$B12) -> 0 | H12: =COUNTIFS('SEPT DUMP '!$C:$C,'PARTNERS SUMMARY'!$B12,'SEPT DUMP '!$O:$O,"Confirmed") -> 0 | I12: =COUNTIFS('SEPT DUMP '!$C:$C,'PARTNERS SUMMARY'!$B12,'SEPT DUMP '!$O:$O,"Rejected") -> 0 | J12: =COUNTIFS('SEPT DUMP '!$C:$C,'PARTNERS SUMMARY'!$B12,'SEPT DUMP '!$O:$O,"Unreachable") -> 0 | K12: =COUNTIFS('SEPT DUMP '!$C:$C,'PARTNERS SUMMARY'!$B12,'SEPT DUMP '!$O:$O,"Postponed(Update Y)") -> 0 | L12: =SUM(AH12:BK12) -> 0 | M12: =IFERROR(L12/G12,0) -> 0 | O12: =COUNTIF('OCT DUMP'!$D:$D,'PARTNERS SUMMARY'!$B12) -> 7 | P12: =COUNTIFS('OCT DUMP'!$D:$D,'PARTNERS SUMMARY'!$B12,'OCT DUMP'!Q:Q,"Prospect") -> 0 | Q12: =COUNTIFS('OCT DUMP'!$D:$D,'PARTNERS SUMMARY'!$B12,'OCT DUMP'!$Q:$Q,"Confirmed") -> 5 | R12: =COUNTIFS('OCT DUMP'!$D:$D,'PARTNERS SUMMARY'!$B12,'OCT DUMP'!$Q:$Q,"Rejected") -> 1 | S12: =COUNTIFS('OCT DUMP'!$D:$D,'PARTNERS SUMMARY'!$B12,'OCT DUMP'!$Q:$Q,"Unreachable") -> 1 | T12: =COUNTIFS('OCT DUMP'!$D:$D,'PARTNERS SUMMARY'!$B12,'OCT DUMP'!$Q:$Q,"Postponed(Update Y)") -> 0 | U12: =SUM(BL12:CP12) -> 2 | V12: =IFERROR(U12/O12,0) -> 0.28571429 | X12: =COUNTIF('NOV DUMP'!C:C,'PARTNERS SUMMARY'!$B12) -> 2 | Y12: =COUNTIFS('NOV DUMP'!$C:$C,'PARTNERS SUMMARY'!$B12,'NOV DUMP'!$S:$S,"Prospect") -> 0 | Z12: =COUNTIFS('NOV DUMP'!$C:$C,'PARTNERS SUMMARY'!$B12,'NOV DUMP'!$S:$S,"Confirmed") -> 1 | AA12: =COUNTIFS('NOV DUMP'!$C:$C,'PARTNERS SUMMARY'!$B12,'NOV DUMP'!$S:$S,"Rejected") -> 0 | AB12: =COUNTIFS('NOV DUMP'!$C:$C,'PARTNERS SUMMARY'!$B12,'NOV DUMP'!$S:$S,"Unreachable") -> 0 | AC12: =COUNTIFS('NOV DUMP'!$C:$C,'PARTNERS SUMMARY'!$B12,'NOV DUMP'!$S:$S,"Postponed(Update Y)") -> 0 | AD12: =SUM(CQ12:DT12) -> 1 | AE12: =COUNTIFS('ACTIVATED LEADS '!$H:$H,'PARTNERS SUMMARY'!$B12,'ACTIVATED LEADS '!$K:$K,'PARTNERS SUMMARY'!$AE$2,'ACTIVATED LEADS '!$C:$C,"16") -> 1 | AF12: =IFERROR(AD12/X12,0) -> 0.5 | AH12: =COUNTIFS('ACTIVATED LEADS '!$H:$H,$B12,'ACTIVATED LEADS '!$D:$D,'PARTNERS SUMMARY'!AH$3) -> 0 | AI12: =COUNTIFS('ACTIVATED LEADS '!$H:$H,$B12,'ACTIVATED LEADS '!$D:$D,'PARTNERS SUMMARY'!AI$3) -> 0 | AJ12: =COUNTIFS('ACTIVATED LEADS '!$H:$H,$B12,'ACTIVATED LEADS '!$D:$D,'PARTNERS SUMMARY'!AJ$3) -> 0 | AK12: =COUNTIFS('ACTIVATED LEADS '!$H:$H,$B12,'ACTIVATED LEADS '!$D:$D,'PARTNERS SUMMARY'!AK$3) -> 0 | AL12: =COUNTIFS('ACTIVATED LEADS '!$H:$H,$B12,'ACTIVATED LEADS '!$D:$D,'PARTNERS SUMMARY'!AL$3) -> 0 | AM12: =COUNTIFS('ACTIVATED LEADS '!$H:$H,$B12,'ACTIVATED LEADS '!$D:$D,'PARTNERS SUMMARY'!AM$3) -> 0 | AN12: =COUNTIFS('ACTIVATED LEADS '!$H:$H,$B12,'ACTIVATED LEADS '!$D:$D,'PARTNERS SUMMARY'!AN$3) -> 0 | AO12: =COUNTIFS('ACTIVATED LEADS '!$H:$H,$B12,'ACTIVATED LEADS '!$D:$D,'PARTNERS SUMMARY'!AO$3) -> 0 | ... DO12: =COUNTIFS('ACTIVATED LEADS '!$H:$H,$B12,'ACTIVATED LEADS '!$D:$D,'PARTNERS SUMMARY'!DO$3) -> 0
A13: Damaris Mainga | B13: SALAMA COMMUNICATIONS LIMITED | C13: 782036662 | D13: Nyumujacinta@gmail.com | E13: Machakos | F13: Nairobi | G13: =COUNTIF('SEPT DUMP '!$C:$C,'PARTNERS SUMMARY'!$B13) -> 0 | H13: =COUNTIFS('SEPT DUMP '!$C:$C,'PARTNERS SUMMARY'!$B13,'SEPT DUMP '!$O:$O,"Confirmed") -> 0 | I13: =COUNTIFS('SEPT DUMP '!$C:$C,'PARTNERS SUMMARY'!$B13,'SEPT DUMP '!$O:$O,"Rejected") -> 0 | J13: =COUNTIFS('SEPT DUMP '!$C:$C,'PARTNERS SUMMARY'!$B13,'SEPT DUMP '!$O:$O,"Unreachable") -> 0 | K13: =COUNTIFS('SEPT DUMP '!$C:$C,'PARTNERS SUMMARY'!$B13,'SEPT DUMP '!$O:$O,"Postponed(Update Y)") -> 0 | L13: =SUM(AH13:BK13) -> 0 | M13: =IFERROR(L13/G13,0) -> 0 | O13: =COUNTIF('OCT DUMP'!$D:$D,'PARTNERS SUMMARY'!$B13) -> 13 | P13: =COUNTIFS('OCT DUMP'!$D:$D,'PARTNERS SUMMARY'!$B13,'OCT DUMP'!Q:Q,"Prospect") -> 0 | Q13: =COUNTIFS('OCT DUMP'!$D:$D,'PARTNERS SUMMARY'!$B13,'OCT DUMP'!$Q:$Q,"Confirmed") -> 5 | R13: =COUNTIFS('OCT DUMP'!$D:$D,'PARTNERS SUMMARY'!$B13,'OCT DUMP'!$Q:$Q,"Rejected") -> 6 | S13: =COUNTIFS('OCT DUMP'!$D:$D,'PARTNERS SUMMARY'!$B13,'OCT DUMP'!$Q:$Q,"Unreachable") -> 2 | T13: =COUNTIFS('OCT DUMP'!$D:$D,'PARTNERS SUMMARY'!$B13,'OCT DUMP'!$Q:$Q,"Postponed(Update Y)") -> 0 | U13: =SUM(BL13:CP13) -> 5 | V13: =IFERROR(U13/O13,0) -> 0.38461538 | X13: =COUNTIF('NOV DUMP'!C:C,'PARTNERS SUMMARY'!$B13) -> 29 | Y13: =COUNTIFS('NOV DUMP'!$C:$C,'PARTNERS SUMMARY'!$B13,'NOV DUMP'!$S:$S,"Prospect") -> 1 | Z13: =COUNTIFS('NOV DUMP'!$C:$C,'PARTNERS SUMMARY'!$B13,'NOV DUMP'!$S:$S,"Confirmed") -> 2 | AA13: =COUNTIFS('NOV DUMP'!$C:$C,'PARTNERS SUMMARY'!$B13,'NOV DUMP'!$S:$S,"Rejected") -> 1 | AB13: =COUNTIFS('NOV DUMP'!$C:$C,'PARTNERS SUMMARY'!$B13,'NOV DUMP'!$S:$S,"Unreachable") -> 0 | AC13: =COUNTIFS('NOV DUMP'!$C:$C,'PARTNERS SUMMARY'!$B13,'NOV DUMP'!$S:$S,"Postponed(Update Y)") -> 0 | AD13: =SUM(CQ13:DT13) -> 9 | AE13: =COUNTIFS('ACTIVATED LEADS '!$H:$H,'PARTNERS SUMMARY'!$B13,'ACTIVATED LEADS '!$K:$K,'PARTNERS SUMMARY'!$AE$2,'ACTIVATED LEADS '!$C:$C,"16") -> 7 | AF13: =IFERROR(AD13/X13,0) -> 0.31034483 | AH13: =COUNTIFS('ACTIVATED LEADS '!$H:$H,$B13,'ACTIVATED LEADS '!$D:$D,'PARTNERS SUMMARY'!AH$3) -> 0 | AI13: =COUNTIFS('ACTIVATED LEADS '!$H:$H,$B13,'ACTIVATED LEADS '!$D:$D,'PARTNERS SUMMARY'!AI$3) -> 0 | AJ13: =COUNTIFS('ACTIVATED LEADS '!$H:$H,$B13,'ACTIVATED LEADS '!$D:$D,'PARTNERS SUMMARY'!AJ$3) -> 0 | AK13: =COUNTIFS('ACTIVATED LEADS '!$H:$H,$B13,'ACTIVATED LEADS '!$D:$D,'PARTNERS SUMMARY'!AK$3) -> 0 | AL13: =COUNTIFS('ACTIVATED LEADS '!$H:$H,$B13,'ACTIVATED LEADS '!$D:$D,'PARTNERS SUMMARY'!AL$3) -> 0 | AM13: =COUNTIFS('ACTIVATED LEADS '!$H:$H,$B13,'ACTIVATED LEADS '!$D:$D,'PARTNERS SUMMARY'!AM$3) -> 0 | AN13: =COUNTIFS('ACTIVATED LEADS '!$H:$H,$B13,'ACTIVATED LEADS '!$D:$D,'PARTNERS SUMMARY'!AN$3) -> 0 | AO13: =COUNTIFS('ACTIVATED LEADS '!$H:$H,$B13,'ACTIVATED LEADS '!$D:$D,'PARTNERS SUMMARY'!AO$3) -> 0 | ... DO13: =COUNTIFS('ACTIVATED LEADS '!$H:$H,$B13,'ACTIVATED LEADS '!$D:$D,'PARTNERS SUMMARY'!DO$3) -> 1
A14: Damaris Mainga | B14: AIRTIME TRADERS LIMITED | C14: 103339563 | D14: Codhiambo386@gmail.com | E14: NAIROBI TOWN | F14: Nairobi | G14: =COUNTIF('SEPT DUMP '!$C:$C,'PARTNERS SUMMARY'!$B14) -> 1 | H14: =COUNTIFS('SEPT DUMP '!$C:$C,'PARTNERS SUMMARY'!$B14,'SEPT DUMP '!$O:$O,"Confirmed") -> 0 | I14: =COUNTIFS('SEPT DUMP '!$C:$C,'PARTNERS SUMMARY'!$B14,'SEPT DUMP '!$O:$O,"Rejected") -> 0 | J14: =COUNTIFS('SEPT DUMP '!$C:$C,'PARTNERS SUMMARY'!$B14,'SEPT DUMP '!$O:$O,"Unreachable") -> 0 | K14: =COUNTIFS('SEPT DUMP '!$C:$C,'PARTNERS SUMMARY'!$B14,'SEPT DUMP '!$O:$O,"Postponed(Update Y)") -> 1 | L14: =SUM(AH14:BK14) -> 0 | M14: =IFERROR(L14/G14,0) -> 0 | O14: =COUNTIF('OCT DUMP'!$D:$D,'PARTNERS SUMMARY'!$B14) -> 15 | P14: =COUNTIFS('OCT DUMP'!$D:$D,'PARTNERS SUMMARY'!$B14,'OCT DUMP'!Q:Q,"Prospect") -> 3 | Q14: =COUNTIFS('OCT DUMP'!$D:$D,'PARTNERS SUMMARY'!$B14,'OCT DUMP'!$Q:$Q,"Confirmed") -> 7 | R14: =COUNTIFS('OCT DUMP'!$D:$D,'PARTNERS SUMMARY'!$B14,'OCT DUMP'!$Q:$Q,"Rejected") -> 3 | S14: =COUNTIFS('OCT DUMP'!$D:$D,'PARTNERS SUMMARY'!$B14,'OCT DUMP'!$Q:$Q,"Unreachable") -> 2 | T14: =COUNTIFS('OCT DUMP'!$D:$D,'PARTNERS SUMMARY'!$B14,'OCT DUMP'!$Q:$Q,"Postponed(Update Y)") -> 0 | U14: =SUM(BL14:CP14) -> 1 | V14: =IFERROR(U14/O14,0) -> 0.066666667 | X14: =COUNTIF('NOV DUMP'!C:C,'PARTNERS SUMMARY'!$B14) -> 37 | Y14: =COUNTIFS('NOV DUMP'!$C:$C,'PARTNERS SUMMARY'!$B14,'NOV DUMP'!$S:$S,"Prospect") -> 0 | Z14: =COUNTIFS('NOV DUMP'!$C:$C,'PARTNERS SUMMARY'!$B14,'NOV DUMP'!$S:$S,"Confirmed") -> 14 | AA14: =COUNTIFS('NOV DUMP'!$C:$C,'PARTNERS SUMMARY'!$B14,'NOV DUMP'!$S:$S,"Rejected") -> 1 | AB14: =COUNTIFS('NOV DUMP'!$C:$C,'PARTNERS SUMMARY'!$B14,'NOV DUMP'!$S:$S,"Unreachable") -> 0 | AC14: =COUNTIFS('NOV DUMP'!$C:$C,'PARTNERS SUMMARY'!$B14,'NOV DUMP'!$S:$S,"Postponed(Update Y)") -> 0 | AD14: =SUM(CQ14:DT14) -> 10 | AE14: =COUNTIFS('ACTIVATED LEADS '!$H:$H,'PARTNERS SUMMARY'!$B14,'ACTIVATED LEADS '!$K:$K,'PARTNERS SUMMARY'!$AE$2,'ACTIVATED LEADS '!$C:$C,"16") -> 10 | AF14: =IFERROR(AD14/X14,0) -> 0.27027027 | AH14: =COUNTIFS('ACTIVATED LEADS '!$H:$H,$B14,'ACTIVATED LEADS '!$D:$D,'PARTNERS SUMMARY'!AH$3) -> 0 | AI14: =COUNTIFS('ACTIVATED LEADS '!$H:$H,$B14,'ACTIVATED LEADS '!$D:$D,'PARTNERS SUMMARY'!AI$3) -> 0 | AJ14: =COUNTIFS('ACTIVATED LEADS '!$H:$H,$B14,'ACTIVATED LEADS '!$D:$D,'PARTNERS SUMMARY'!AJ$3) -> 0 | AK14: =COUNTIFS('ACTIVATED LEADS '!$H:$H,$B14,'ACTIVATED LEADS '!$D:$D,'PARTNERS SUMMARY'!AK$3) -> 0 | AL14: =COUNTIFS('ACTIVATED LEADS '!$H:$H,$B14,'ACTIVATED LEADS '!$D:$D,'PARTNERS SUMMARY'!AL$3) -> 0 | AM14: =COUNTIFS('ACTIVATED LEADS '!$H:$H,$B14,'ACTIVATED LEADS '!$D:$D,'PARTNERS SUMMARY'!AM$3) -> 0 | AN14: =COUNTIFS('ACTIVATED LEADS '!$H:$H,$B14,'ACTIVATED LEADS '!$D:$D,'PARTNERS SUMMARY'!AN$3) -> 0 | AO14: =COUNTIFS('ACTIVATED LEADS '!$H:$H,$B14,'ACTIVATED LEADS '!$D:$D,'PARTNERS SUMMARY'!AO$3) -> 0 | ... DO14: =COUNTIFS('ACTIVATED LEADS '!$H:$H,$B14,'ACTIVATED LEADS '!$D:$D,'PARTNERS SUMMARY'!DO$3) -> 0
A15: Brian Odero | B15: HIDAWEY ENTERPRISE LIMITED | C15: 729062128 | D15: iomach54@gmail.com | E15: Nairobi CBD | F15: Nairobi | G15: =COUNTIF('SEPT DUMP '!$C:$C,'PARTNERS SUMMARY'!$B15) -> 0 | H15: =COUNTIFS('SEPT DUMP '!$C:$C,'PARTNERS SUMMARY'!$B15,'SEPT DUMP '!$O:$O,"Confirmed") -> 0 | I15: =COUNTIFS('SEPT DUMP '!$C:$C,'PARTNERS SUMMARY'!$B15,'SEPT DUMP '!$O:$O,"Rejected") -> 0 | J15: =COUNTIFS('SEPT DUMP '!$C:$C,'PARTNERS SUMMARY'!$B15,'SEPT DUMP '!$O:$O,"Unreachable") -> 0 | K15: =COUNTIFS('SEPT DUMP '!$C:$C,'PARTNERS SUMMARY'!$B15,'SEPT DUMP '!$O:$O,"Postponed(Update Y)") -> 0 | L15: =SUM(AH15:BK15) -> 0 | M15: =IFERROR(L15/G15,0) -> 0 | O15: =COUNTIF('OCT DUMP'!$D:$D,'PARTNERS SUMMARY'!$B15) -> 3 | P15: =COUNTIFS('OCT DUMP'!$D:$D,'PARTNERS SUMMARY'!$B15,'OCT DUMP'!Q:Q,"Prospect") -> 0 | Q15: =COUNTIFS('OCT DUMP'!$D:$D,'PARTNERS SUMMARY'!$B15,'OCT DUMP'!$Q:$Q,"Confirmed") -> 1 | R15: =COUNTIFS('OCT DUMP'!$D:$D,'PARTNERS SUMMARY'!$B15,'OCT DUMP'!$Q:$Q,"Rejected") -> 2 | S15: =COUNTIFS('OCT DUMP'!$D:$D,'PARTNERS SUMMARY'!$B15,'OCT DUMP'!$Q:$Q,"Unreachable") -> 0 | T15: =COUNTIFS('OCT DUMP'!$D:$D,'PARTNERS SUMMARY'!$B15,'OCT DUMP'!$Q:$Q,"Postponed(Update Y)") -> 0 | U15: =SUM(BL15:CP15) -> 0 | V15: =IFERROR(U15/O15,0) -> 0 | X15: =COUNTIF('NOV DUMP'!C:C,'PARTNERS SUMMARY'!$B15) -> 0 | Y15: =COUNTIFS('NOV DUMP'!$C:$C,'PARTNERS SUMMARY'!$B15,'NOV DUMP'!$S:$S,"Prospect") -> 0 | Z15: =COUNTIFS('NOV DUMP'!$C:$C,'PARTNERS SUMMARY'!$B15,'NOV DUMP'!$S:$S,"Confirmed") -> 0 | AA15: =COUNTIFS('NOV DUMP'!$C:$C,'PARTNERS SUMMARY'!$B15,'NOV DUMP'!$S:$S,"Rejected") -> 0 | AB15: =COUNTIFS('NOV DUMP'!$C:$C,'PARTNERS SUMMARY'!$B15,'NOV DUMP'!$S:$S,"Unreachable") -> 0 | AC15: =COUNTIFS('NOV DUMP'!$C:$C,'PARTNERS SUMMARY'!$B15,'NOV DUMP'!$S:$S,"Postponed(Update Y)") -> 0 | AD15: =SUM(CQ15:DT15) -> 1 | AE15: =COUNTIFS('ACTIVATED LEADS '!$H:$H,'PARTNERS SUMMARY'!$B15,'ACTIVATED LEADS '!$K:$K,'PARTNERS SUMMARY'!$AE$2,'ACTIVATED LEADS '!$C:$C,"16") -> 1 | AF15: =IFERROR(AD15/X15,0) -> 0 | AH15: =COUNTIFS('ACTIVATED LEADS '!$H:$H,$B15,'ACTIVATED LEADS '!$D:$D,'PARTNERS SUMMARY'!AH$3) -> 0 | AI15: =COUNTIFS('ACTIVATED LEADS '!$H:$H,$B15,'ACTIVATED LEADS '!$D:$D,'PARTNERS SUMMARY'!AI$3) -> 0 | AJ15: =COUNTIFS('ACTIVATED LEADS '!$H:$H,$B15,'ACTIVATED LEADS '!$D:$D,'PARTNERS SUMMARY'!AJ$3) -> 0 | AK15: =COUNTIFS('ACTIVATED LEADS '!$H:$H,$B15,'ACTIVATED LEADS '!$D:$D,'PARTNERS SUMMARY'!AK$3) -> 0 | AL15: =COUNTIFS('ACTIVATED LEADS '!$H:$H,$B15,'ACTIVATED LEADS '!$D:$D,'PARTNERS SUMMARY'!AL$3) -> 0 | AM15: =COUNTIFS('ACTIVATED LEADS '!$H:$H,$B15,'ACTIVATED LEADS '!$D:$D,'PARTNERS SUMMARY'!AM$3) -> 0 | AN15: =COUNTIFS('ACTIVATED LEADS '!$H:$H,$B15,'ACTIVATED LEADS '!$D:$D,'PARTNERS SUMMARY'!AN$3) -> 0 | AO15: =COUNTIFS('ACTIVATED LEADS '!$H:$H,$B15,'ACTIVATED LEADS '!$D:$D,'PARTNERS SUMMARY'!AO$3) -> 0 | ... DO15: =COUNTIFS('ACTIVATED LEADS '!$H:$H,$B15,'ACTIVATED LEADS '!$D:$D,'PARTNERS SUMMARY'!DO$3) -> 0
... A17: Damaris Mainga | B17: M NET TECHNOLOGIES | C17: 731396245 | D17: damanja12@gmail.com | E17: Gumba | F17: Nairobi | G17: =COUNTIF('SEPT DUMP '!$C:$C,'PARTNERS SUMMARY'!$B17) -> 0 | H17: =COUNTIFS('SEPT DUMP '!$C:$C,'PARTNERS SUMMARY'!$B17,'SEPT DUMP '!$O:$O,"Confirmed") -> 0 | I17: =COUNTIFS('SEPT DUMP '!$C:$C,'PARTNERS SUMMARY'!$B17,'SEPT DUMP '!$O:$O,"Rejected") -> 0 | J17: =COUNTIFS('SEPT DUMP '!$C:$C,'PARTNERS SUMMARY'!$B17,'SEPT DUMP '!$O:$O,"Unreachable") -> 0 | K17: =COUNTIFS('SEPT DUMP '!$C:$C,'PARTNERS SUMMARY'!$B17,'SEPT DUMP '!$O:$O,"Postponed(Update Y)") -> 0 | L17: =SUM(AH17:BK17) -> 0 | M17: =IFERROR(L17/G17,0) -> 0 | O17: =COUNTIF('OCT DUMP'!$D:$D,'PARTNERS SUMMARY'!$B17) -> 12 | P17: =COUNTIFS('OCT DUMP'!$D:$D,'PARTNERS SUMMARY'!$B17,'OCT DUMP'!Q:Q,"Prospect") -> 1 | Q17: =COUNTIFS('OCT DUMP'!$D:$D,'PARTNERS SUMMARY'!$B17,'OCT DUMP'!$Q:$Q,"Confirmed") -> 7 | R17: =COUNTIFS('OCT DUMP'!$D:$D,'PARTNERS SUMMARY'!$B17,'OCT DUMP'!$Q:$Q,"Rejected") -> 3 | S17: =COUNTIFS('OCT DUMP'!$D:$D,'PARTNERS SUMMARY'!$B17,'OCT DUMP'!$Q:$Q,"Unreachable") -> 0 | T17: =COUNTIFS('OCT DUMP'!$D:$D,'PARTNERS SUMMARY'!$B17,'OCT DUMP'!$Q:$Q,"Postponed(Update Y)") -> 1 | U17: =SUM(BL17:CP17) -> 0 | V17: =IFERROR(U17/O17,0) -> 0 | X17: =COUNTIF('NOV DUMP'!C:C,'PARTNERS SUMMARY'!$B17) -> 7 | Y17: =COUNTIFS('NOV DUMP'!$C:$C,'PARTNERS SUMMARY'!$B17,'NOV DUMP'!$S:$S,"Prospect") -> 0 | Z17: =COUNTIFS('NOV DUMP'!$C:$C,'PARTNERS SUMMARY'!$B17,'NOV DUMP'!$S:$S,"Confirmed") -> 1 | AA17: =COUNTIFS('NOV DUMP'!$C:$C,'PARTNERS SUMMARY'!$B17,'NOV DUMP'!$S:$S,"Rejected") -> 1 | AB17: =COUNTIFS('NOV DUMP'!$C:$C,'PARTNERS SUMMARY'!$B17,'NOV DUMP'!$S:$S,"Unreachable") -> 0 | AC17: =COUNTIFS('NOV DUMP'!$C:$C,'PARTNERS SUMMARY'!$B17,'NOV DUMP'!$S:$S,"Postponed(Update Y)") -> 0 | AD17: =SUM(CQ17:DT17) -> 1 | AE17: =COUNTIFS('ACTIVATED LEADS '!$H:$H,'PARTNERS SUMMARY'!$B17,'ACTIVATED LEADS '!$K:$K,'PARTNERS SUMMARY'!$AE$2,'ACTIVATED LEADS '!$C:$C,"16") -> 0 | AF17: =IFERROR(AD17/X17,0) -> 0.14285714 | AH17: =COUNTIFS('ACTIVATED LEADS '!$H:$H,$B17,'ACTIVATED LEADS '!$D:$D,'PARTNERS SUMMARY'!AH$3) -> 0 | AI17: =COUNTIFS('ACTIVATED LEADS '!$H:$H,$B17,'ACTIVATED LEADS '!$D:$D,'PARTNERS SUMMARY'!AI$3) -> 0 | AJ17: =COUNTIFS('ACTIVATED LEADS '!$H:$H,$B17,'ACTIVATED LEADS '!$D:$D,'PARTNERS SUMMARY'!AJ$3) -> 0 | AK17: =COUNTIFS('ACTIVATED LEADS '!$H:$H,$B17,'ACTIVATED LEADS '!$D:$D,'PARTNERS SUMMARY'!AK$3) -> 0 | AL17: =COUNTIFS('ACTIVATED LEADS '!$H:$H,$B17,'ACTIVATED LEADS '!$D:$D,'PARTNERS SUMMARY'!AL$3) -> 0 | AM17: =COUNTIFS('ACTIVATED LEADS '!$H:$H,$B17,'ACTIVATED LEADS '!$D:$D,'PARTNERS SUMMARY'!AM$3) -> 0 | AN17: =COUNTIFS('ACTIVATED LEADS '!$H:$H,$B17,'ACTIVATED LEADS '!$D:$D,'PARTNERS SUMMARY'!AN$3) -> 0 | AO17: =COUNTIFS('ACTIVATED LEADS '!$H:$H,$B17,'ACTIVATED LEADS '!$D:$D,'PARTNERS SUMMARY'!AO$3) -> 0 | ... DO17: =COUNTIFS('ACTIVATED LEADS '!$H:$H,$B17,'ACTIVATED LEADS '!$D:$D,'PARTNERS SUMMARY'!DO$3) -> 0
A18: Brian Odero | B18: TORESCOE LIMITED | C18: 733262252 | D18: info@torescoe.com | F18: Nairobi | G18: =COUNTIF('SEPT DUMP '!$C:$C,'PARTNERS SUMMARY'!$B18) -> 0 | H18: =COUNTIFS('SEPT DUMP '!$C:$C,'PARTNERS SUMMARY'!$B18,'SEPT DUMP '!$O:$O,"Confirmed") -> 0 | I18: =COUNTIFS('SEPT DUMP '!$C:$C,'PARTNERS SUMMARY'!$B18,'SEPT DUMP '!$O:$O,"Rejected") -> 0 | J18: =COUNTIFS('SEPT DUMP '!$C:$C,'PARTNERS SUMMARY'!$B18,'SEPT DUMP '!$O:$O,"Unreachable") -> 0 | K18: =COUNTIFS('SEPT DUMP '!$C:$C,'PARTNERS SUMMARY'!$B18,'SEPT DUMP '!$O:$O,"Postponed(Update Y)") -> 0 | L18: =SUM(AH18:BK18) -> 0 | M18: =IFERROR(L18/G18,0) -> 0 | O18: =COUNTIF('OCT DUMP'!$D:$D,'PARTNERS SUMMARY'!$B18) -> 2 | P18: =COUNTIFS('OCT DUMP'!$D:$D,'PARTNERS SUMMARY'!$B18,'OCT DUMP'!Q:Q,"Prospect") -> 0 | Q18: =COUNTIFS('OCT DUMP'!$D:$D,'PARTNERS SUMMARY'!$B18,'OCT DUMP'!$Q:$Q,"Confirmed") -> 0 | R18: =COUNTIFS('OCT DUMP'!$D:$D,'PARTNERS SUMMARY'!$B18,'OCT DUMP'!$Q:$Q,"Rejected") -> 0 | S18: =COUNTIFS('OCT DUMP'!$D:$D,'PARTNERS SUMMARY'!$B18,'OCT DUMP'!$Q:$Q,"Unreachable") -> 2 | T18: =COUNTIFS('OCT DUMP'!$D:$D,'PARTNERS SUMMARY'!$B18,'OCT DUMP'!$Q:$Q,"Postponed(Update Y)") -> 0 | U18: =SUM(BL18:CP18) -> 0 | V18: =IFERROR(U18/O18,0) -> 0 | X18: =COUNTIF('NOV DUMP'!C:C,'PARTNERS SUMMARY'!$B18) -> 1 | Y18: =COUNTIFS('NOV DUMP'!$C:$C,'PARTNERS SUMMARY'!$B18,'NOV DUMP'!$S:$S,"Prospect") -> 0 | Z18: =COUNTIFS('NOV DUMP'!$C:$C,'PARTNERS SUMMARY'!$B18,'NOV DUMP'!$S:$S,"Confirmed") -> 0 | AA18: =COUNTIFS('NOV DUMP'!$C:$C,'PARTNERS SUMMARY'!$B18,'NOV DUMP'!$S:$S,"Rejected") -> 0 | AB18: =COUNTIFS('NOV DUMP'!$C:$C,'PARTNERS SUMMARY'!$B18,'NOV DUMP'!$S:$S,"Unreachable") -> 0 | AC18: =COUNTIFS('NOV DUMP'!$C:$C,'PARTNERS SUMMARY'!$B18,'NOV DUMP'!$S:$S,"Postponed(Update Y)") -> 0 | AD18: =SUM(CQ18:DT18) -> 1 | AE18: =COUNTIFS('ACTIVATED LEADS '!$H:$H,'PARTNERS SUMMARY'!$B18,'ACTIVATED LEADS '!$K:$K,'PARTNERS SUMMARY'!$AE$2,'ACTIVATED LEADS '!$C:$C,"16") -> 1 | AF18: =IFERROR(AD18/X18,0) -> 1 | AH18: =COUNTIFS('ACTIVATED LEADS '!$H:$H,$B18,'ACTIVATED LEADS '!$D:$D,'PARTNERS SUMMARY'!AH$3) -> 0 | AI18: =COUNTIFS('ACTIVATED LEADS '!$H:$H,$B18,'ACTIVATED LEADS '!$D:$D,'PARTNERS SUMMARY'!AI$3) -> 0 | AJ18: =COUNTIFS('ACTIVATED LEADS '!$H:$H,$B18,'ACTIVATED LEADS '!$D:$D,'PARTNERS SUMMARY'!AJ$3) -> 0 | AK18: =COUNTIFS('ACTIVATED LEADS '!$H:$H,$B18,'ACTIVATED LEADS '!$D:$D,'PARTNERS SUMMARY'!AK$3) -> 0 | AL18: =COUNTIFS('ACTIVATED LEADS '!$H:$H,$B18,'ACTIVATED LEADS '!$D:$D,'PARTNERS SUMMARY'!AL$3) -> 0 | AM18: =COUNTIFS('ACTIVATED LEADS '!$H:$H,$B18,'ACTIVATED LEADS '!$D:$D,'PARTNERS SUMMARY'!AM$3) -> 0 | AN18: =COUNTIFS('ACTIVATED LEADS '!$H:$H,$B18,'ACTIVATED LEADS '!$D:$D,'PARTNERS SUMMARY'!AN$3) -> 0 | AO18: =COUNTIFS('ACTIVATED LEADS '!$H:$H,$B18,'ACTIVATED LEADS '!$D:$D,'PARTNERS SUMMARY'!AO$3) -> 0 | ... DO18: =COUNTIFS('ACTIVATED LEADS '!$H:$H,$B18,'ACTIVATED LEADS '!$D:$D,'PARTNERS SUMMARY'!DO$3) -> 0
A19: Betreace Chebet | B19: KACHO INVESTMENT | C19: 738748828 | D19: kachoinvestment@gmail.com | E19: Nakuru Town | F19: Rift | G19: =COUNTIF('SEPT DUMP '!$C:$C,'PARTNERS SUMMARY'!$B19) -> 0 | H19: =COUNTIFS('SEPT DUMP '!$C:$C,'PARTNERS SUMMARY'!$B19,'SEPT DUMP '!$O:$O,"Confirmed") -> 0 | I19: =COUNTIFS('SEPT DUMP '!$C:$C,'PARTNERS SUMMARY'!$B19,'SEPT DUMP '!$O:$O,"Rejected") -> 0 | J19: =COUNTIFS('SEPT DUMP '!$C:$C,'PARTNERS SUMMARY'!$B19,'SEPT DUMP '!$O:$O,"Unreachable") -> 0 | K19: =COUNTIFS('SEPT DUMP '!$C:$C,'PARTNERS SUMMARY'!$B19,'SEPT DUMP '!$O:$O,"Postponed(Update Y)") -> 0 | L19: =SUM(AH19:BK19) -> 0 | M19: =IFERROR(L19/G19,0) -> 0 | O19: =COUNTIF('OCT DUMP'!$D:$D,'PARTNERS SUMMARY'!$B19) -> 4 | P19: =COUNTIFS('OCT DUMP'!$D:$D,'PARTNERS SUMMARY'!$B19,'OCT DUMP'!Q:Q,"Prospect") -> 0 | Q19: =COUNTIFS('OCT DUMP'!$D:$D,'PARTNERS SUMMARY'!$B19,'OCT DUMP'!$Q:$Q,"Confirmed") -> 4 | R19: =COUNTIFS('OCT DUMP'!$D:$D,'PARTNERS SUMMARY'!$B19,'OCT DUMP'!$Q:$Q,"Rejected") -> 0 | S19: =COUNTIFS('OCT DUMP'!$D:$D,'PARTNERS SUMMARY'!$B19,'OCT DUMP'!$Q:$Q,"Unreachable") -> 0 | T19: =COUNTIFS('OCT DUMP'!$D:$D,'PARTNERS SUMMARY'!$B19,'OCT DUMP'!$Q:$Q,"Postponed(Update Y)") -> 0 | U19: =SUM(BL19:CP19) -> 0 | V19: =IFERROR(U19/O19,0) -> 0 | X19: =COUNTIF('NOV DUMP'!C:C,'PARTNERS SUMMARY'!$B19) -> 2 | Y19: =COUNTIFS('NOV DUMP'!$C:$C,'PARTNERS SUMMARY'!$B19,'NOV DUMP'!$S:$S,"Prospect") -> 0 | Z19: =COUNTIFS('NOV DUMP'!$C:$C,'PARTNERS SUMMARY'!$B19,'NOV DUMP'!$S:$S,"Confirmed") -> 0 | AA19: =COUNTIFS('NOV DUMP'!$C:$C,'PARTNERS SUMMARY'!$B19,'NOV DUMP'!$S:$S,"Rejected") -> 0 | AB19: =COUNTIFS('NOV DUMP'!$C:$C,'PARTNERS SUMMARY'!$B19,'NOV DUMP'!$S:$S,"Unreachable") -> 0 | AC19: =COUNTIFS('NOV DUMP'!$C:$C,'PARTNERS SUMMARY'!$B19,'NOV DUMP'!$S:$S,"Postponed(Update Y)") -> 0 | AD19: =SUM(CQ19:DT19) -> 2 | AE19: =COUNTIFS('ACTIVATED LEADS '!$H:$H,'PARTNERS SUMMARY'!$B19,'ACTIVATED LEADS '!$K:$K,'PARTNERS SUMMARY'!$AE$2,'ACTIVATED LEADS '!$C:$C,"16") -> 1 | AF19: =IFERROR(AD19/X19,0) -> 1 | AH19: =COUNTIFS('ACTIVATED LEADS '!$H:$H,$B19,'ACTIVATED LEADS '!$D:$D,'PARTNERS SUMMARY'!AH$3) -> 0 | AI19: =COUNTIFS('ACTIVATED LEADS '!$H:$H,$B19,'ACTIVATED LEADS '!$D:$D,'PARTNERS SUMMARY'!AI$3) -> 0 | AJ19: =COUNTIFS('ACTIVATED LEADS '!$H:$H,$B19,'ACTIVATED LEADS '!$D:$D,'PARTNERS SUMMARY'!AJ$3) -> 0 | AK19: =COUNTIFS('ACTIVATED LEADS '!$H:$H,$B19,'ACTIVATED LEADS '!$D:$D,'PARTNERS SUMMARY'!AK$3) -> 0 | AL19: =COUNTIFS('ACTIVATED LEADS '!$H:$H,$B19,'ACTIVATED LEADS '!$D:$D,'PARTNERS SUMMARY'!AL$3) -> 0 | AM19: =COUNTIFS('ACTIVATED LEADS '!$H:$H,$B19,'ACTIVATED LEADS '!$D:$D,'PARTNERS SUMMARY'!AM$3) -> 0 | AN19: =COUNTIFS('ACTIVATED LEADS '!$H:$H,$B19,'ACTIVATED LEADS '!$D:$D,'PARTNERS SUMMARY'!AN$3) -> 0 | AO19: =COUNTIFS('ACTIVATED LEADS '!$H:$H,$B19,'ACTIVATED LEADS '!$D:$D,'PARTNERS SUMMARY'!AO$3) -> 0 | ... DO19: =COUNTIFS('ACTIVATED LEADS '!$H:$H,$B19,'ACTIVATED LEADS '!$D:$D,'PARTNERS SUMMARY'!DO$3) -> 0
A20: Brian Odero | B20: AJ KENYA LIMITED | C20: 736284530 | D20: gfredrick15@gmail.com | E20: Westlands, Krishna centre,6th floor | F20: Nairobi | G20: =COUNTIF('SEPT DUMP '!$C:$C,'PARTNERS SUMMARY'!$B20) -> 1 | H20: =COUNTIFS('SEPT DUMP '!$C:$C,'PARTNERS SUMMARY'!$B20,'SEPT DUMP '!$O:$O,"Confirmed") -> 1 | I20: =COUNTIFS('SEPT DUMP '!$C:$C,'PARTNERS SUMMARY'!$B20,'SEPT DUMP '!$O:$O,"Rejected") -> 0 | J20: =COUNTIFS('SEPT DUMP '!$C:$C,'PARTNERS SUMMARY'!$B20,'SEPT DUMP '!$O:$O,"Unreachable") -> 0 | K20: =COUNTIFS('SEPT DUMP '!$C:$C,'PARTNERS SUMMARY'!$B20,'SEPT DUMP '!$O:$O,"Postponed(Update Y)") -> 0 | L20: =SUM(AH20:BK20) -> 0 | M20: =IFERROR(L20/G20,0) -> 0 | O20: =COUNTIF('OCT DUMP'!$D:$D,'PARTNERS SUMMARY'!$B20) -> 0 | P20: =COUNTIFS('OCT DUMP'!$D:$D,'PARTNERS SUMMARY'!$B20,'OCT DUMP'!Q:Q,"Prospect") -> 0 | Q20: =COUNTIFS('OCT DUMP'!$D:$D,'PARTNERS SUMMARY'!$B20,'OCT DUMP'!$Q:$Q,"Confirmed") -> 0 | R20: =COUNTIFS('OCT DUMP'!$D:$D,'PARTNERS SUMMARY'!$B20,'OCT DUMP'!$Q:$Q,"Rejected") -> 0 | S20: =COUNTIFS('OCT DUMP'!$D:$D,'PARTNERS SUMMARY'!$B20,'OCT DUMP'!$Q:$Q,"Unreachable") -> 0 | T20: =COUNTIFS('OCT DUMP'!$D:$D,'PARTNERS SUMMARY'!$B20,'OCT DUMP'!$Q:$Q,"Postponed(Update Y)") -> 0 | U20: =SUM(BL20:CP20) -> 0 | V20: =IFERROR(U20/O20,0) -> 0 | X20: =COUNTIF('NOV DUMP'!C:C,'PARTNERS SUMMARY'!$B20) -> 0 | Y20: =COUNTIFS('NOV DUMP'!$C:$C,'PARTNERS SUMMARY'!$B20,'NOV DUMP'!$S:$S,"Prospect") -> 0 | Z20: =COUNTIFS('NOV DUMP'!$C:$C,'PARTNERS SUMMARY'!$B20,'NOV DUMP'!$S:$S,"Confirmed") -> 0 | AA20: =COUNTIFS('NOV DUMP'!$C:$C,'PARTNERS SUMMARY'!$B20,'NOV DUMP'!$S:$S,"Rejected") -> 0 | AB20: =COUNTIFS('NOV DUMP'!$C:$C,'PARTNERS SUMMARY'!$B20,'NOV DUMP'!$S:$S,"Unreachable") -> 0 | AC20: =COUNTIFS('NOV DUMP'!$C:$C,'PARTNERS SUMMARY'!$B20,'NOV DUMP'!$S:$S,"Postponed(Update Y)") -> 0 | AD20: =SUM(CQ20:DT20) -> 0 | AE20: =COUNTIFS('ACTIVATED LEADS '!$H:$H,'PARTNERS SUMMARY'!$B20,'ACTIVATED LEADS '!$K:$K,'PARTNERS SUMMARY'!$AE$2,'ACTIVATED LEADS '!$C:$C,"16") -> 0 | AF20: =IFERROR(AD20/X20,0) -> 0 | AH20: =COUNTIFS('ACTIVATED LEADS '!$H:$H,$B20,'ACTIVATED LEADS '!$D:$D,'PARTNERS SUMMARY'!AH$3) -> 0 | AI20: =COUNTIFS('ACTIVATED LEADS '!$H:$H,$B20,'ACTIVATED LEADS '!$D:$D,'PARTNERS SUMMARY'!AI$3) -> 0 | AJ20: =COUNTIFS('ACTIVATED LEADS '!$H:$H,$B20,'ACTIVATED LEADS '!$D:$D,'PARTNERS SUMMARY'!AJ$3) -> 0 | AK20: =COUNTIFS('ACTIVATED LEADS '!$H:$H,$B20,'ACTIVATED LEADS '!$D:$D,'PARTNERS SUMMARY'!AK$3) -> 0 | AL20: =COUNTIFS('ACTIVATED LEADS '!$H:$H,$B20,'ACTIVATED LEADS '!$D:$D,'PARTNERS SUMMARY'!AL$3) -> 0 | AM20: =COUNTIFS('ACTIVATED LEADS '!$H:$H,$B20,'ACTIVATED LEADS '!$D:$D,'PARTNERS SUMMARY'!AM$3) -> 0 | AN20: =COUNTIFS('ACTIVATED LEADS '!$H:$H,$B20,'ACTIVATED LEADS '!$D:$D,'PARTNERS SUMMARY'!AN$3) -> 0 | AO20: =COUNTIFS('ACTIVATED LEADS '!$H:$H,$B20,'ACTIVATED LEADS '!$D:$D,'PARTNERS SUMMARY'!AO$3) -> 0 | ... DO20: =COUNTIFS('ACTIVATED LEADS '!$H:$H,$B20,'ACTIVATED LEADS '!$D:$D,'PARTNERS SUMMARY'!DO$3) -> 0
A21: Mariana Hongo | B21: BAMBANET TECHNOLOGIES | C21: 732895814 | D21: calebokonji@gmail.com | F21: Western | G21: =COUNTIF('SEPT DUMP '!$C:$C,'PARTNERS SUMMARY'!$B21) -> 0 | H21: =COUNTIFS('SEPT DUMP '!$C:$C,'PARTNERS SUMMARY'!$B21,'SEPT DUMP '!$O:$O,"Confirmed") -> 0 | I21: =COUNTIFS('SEPT DUMP '!$C:$C,'PARTNERS SUMMARY'!$B21,'SEPT DUMP '!$O:$O,"Rejected") -> 0 | J21: =COUNTIFS('SEPT DUMP '!$C:$C,'PARTNERS SUMMARY'!$B21,'SEPT DUMP '!$O:$O,"Unreachable") -> 0 | K21: =COUNTIFS('SEPT DUMP '!$C:$C,'PARTNERS SUMMARY'!$B21,'SEPT DUMP '!$O:$O,"Postponed(Update Y)") -> 0 | L21: =SUM(AH21:BK21) -> 0 | M21: =IFERROR(L21/G21,0) -> 0 | O21: =COUNTIF('OCT DUMP'!$D:$D,'PARTNERS SUMMARY'!$B21) -> 2 | P21: =COUNTIFS('OCT DUMP'!$D:$D,'PARTNERS SUMMARY'!$B21,'OCT DUMP'!Q:Q,"Prospect") -> 0 | Q21: =COUNTIFS('OCT DUMP'!$D:$D,'PARTNERS SUMMARY'!$B21,'OCT DUMP'!$Q:$Q,"Confirmed") -> 2 | R21: =COUNTIFS('OCT DUMP'!$D:$D,'PARTNERS SUMMARY'!$B21,'OCT DUMP'!$Q:$Q,"Rejected") -> 0 | S21: =COUNTIFS('OCT DUMP'!$D:$D,'PARTNERS SUMMARY'!$B21,'OCT DUMP'!$Q:$Q,"Unreachable") -> 0 | T21: =COUNTIFS('OCT DUMP'!$D:$D,'PARTNERS SUMMARY'!$B21,'OCT DUMP'!$Q:$Q,"Postponed(Update Y)") -> 0 | U21: =SUM(BL21:CP21) -> 1 | V21: =IFERROR(U21/O21,0) -> 0.5 | X21: =COUNTIF('NOV DUMP'!C:C,'PARTNERS SUMMARY'!$B21) -> 0 | Y21: =COUNTIFS('NOV DUMP'!$C:$C,'PARTNERS SUMMARY'!$B21,'NOV DUMP'!$S:$S,"Prospect") -> 0 | Z21: =COUNTIFS('NOV DUMP'!$C:$C,'PARTNERS SUMMARY'!$B21,'NOV DUMP'!$S:$S,"Confirmed") -> 0 | AA21: =COUNTIFS('NOV DUMP'!$C:$C,'PARTNERS SUMMARY'!$B21,'NOV DUMP'!$S:$S,"Rejected") -> 0 | AB21: =COUNTIFS('NOV DUMP'!$C:$C,'PARTNERS SUMMARY'!$B21,'NOV DUMP'!$S:$S,"Unreachable") -> 0 | AC21: =COUNTIFS('NOV DUMP'!$C:$C,'PARTNERS SUMMARY'!$B21,'NOV DUMP'!$S:$S,"Postponed(Update Y)") -> 0 | AD21: =SUM(CQ21:DT21) -> 1 | AE21: =COUNTIFS('ACTIVATED LEADS '!$H:$H,'PARTNERS SUMMARY'!$B21,'ACTIVATED LEADS '!$K:$K,'PARTNERS SUMMARY'!$AE$2,'ACTIVATED LEADS '!$C:$C,"16") -> 1 | AF21: =IFERROR(AD21/X21,0) -> 0 | AH21: =COUNTIFS('ACTIVATED LEADS '!$H:$H,$B21,'ACTIVATED LEADS '!$D:$D,'PARTNERS SUMMARY'!AH$3) -> 0 | AI21: =COUNTIFS('ACTIVATED LEADS '!$H:$H,$B21,'ACTIVATED LEADS '!$D:$D,'PARTNERS SUMMARY'!AI$3) -> 0 | AJ21: =COUNTIFS('ACTIVATED LEADS '!$H:$H,$B21,'ACTIVATED LEADS '!$D:$D,'PARTNERS SUMMARY'!AJ$3) -> 0 | AK21: =COUNTIFS('ACTIVATED LEADS '!$H:$H,$B21,'ACTIVATED LEADS '!$D:$D,'PARTNERS SUMMARY'!AK$3) -> 0 | AL21: =COUNTIFS('ACTIVATED LEADS '!$H:$H,$B21,'ACTIVATED LEADS '!$D:$D,'PARTNERS SUMMARY'!AL$3) -> 0 | AM21: =COUNTIFS('ACTIVATED LEADS '!$H:$H,$B21,'ACTIVATED LEADS '!$D:$D,'PARTNERS SUMMARY'!AM$3) -> 0 | AN21: =COUNTIFS('ACTIVATED LEADS '!$H:$H,$B21,'ACTIVATED LEADS '!$D:$D,'PARTNERS SUMMARY'!AN$3) -> 0 | AO21: =COUNTIFS('ACTIVATED LEADS '!$H:$H,$B21,'ACTIVATED LEADS '!$D:$D,'PARTNERS SUMMARY'!AO$3) -> 0 | ... DO21: =COUNTIFS('ACTIVATED LEADS '!$H:$H,$B21,'ACTIVATED LEADS '!$D:$D,'PARTNERS SUMMARY'!DO$3) -> 0
A22: Brian Odero | B22: LEARNERS BRIDGE SOLUTION | C22: 738895780 | D22: edwinoyugi254@gmail.com | E22: Umoja | F22: Nairobi | G22: =COUNTIF('SEPT DUMP '!$C:$C,'PARTNERS SUMMARY'!$B22) -> 0 | H22: =COUNTIFS('SEPT DUMP '!$C:$C,'PARTNERS SUMMARY'!$B22,'SEPT DUMP '!$O:$O,"Confirmed") -> 0 | I22: =COUNTIFS('SEPT DUMP '!$C:$C,'PARTNERS SUMMARY'!$B22,'SEPT DUMP '!$O:$O,"Rejected") -> 0 | J22: =COUNTIFS('SEPT DUMP '!$C:$C,'PARTNERS SUMMARY'!$B22,'SEPT DUMP '!$O:$O,"Unreachable") -> 0 | K22: =COUNTIFS('SEPT DUMP '!$C:$C,'PARTNERS SUMMARY'!$B22,'SEPT DUMP '!$O:$O,"Postponed(Update Y)") -> 0 | L22: =SUM(AH22:BK22) -> 0 | M22: =IFERROR(L22/G22,0) -> 0 | O22: =COUNTIF('OCT DUMP'!$D:$D,'PARTNERS SUMMARY'!$B22) -> 2 | P22: =COUNTIFS('OCT DUMP'!$D:$D,'PARTNERS SUMMARY'!$B22,'OCT DUMP'!Q:Q,"Prospect") -> 0 | Q22: =COUNTIFS('OCT DUMP'!$D:$D,'PARTNERS SUMMARY'!$B22,'OCT DUMP'!$Q:$Q,"Confirmed") -> 0 | R22: =COUNTIFS('OCT DUMP'!$D:$D,'PARTNERS SUMMARY'!$B22,'OCT DUMP'!$Q:$Q,"Rejected") -> 2 | S22: =COUNTIFS('OCT DUMP'!$D:$D,'PARTNERS SUMMARY'!$B22,'OCT DUMP'!$Q:$Q,"Unreachable") -> 0 | T22: =COUNTIFS('OCT DUMP'!$D:$D,'PARTNERS SUMMARY'!$B22,'OCT DUMP'!$Q:$Q,"Postponed(Update Y)") -> 0 | U22: =SUM(BL22:CP22) -> 0 | V22: =IFERROR(U22/O22,0) -> 0 | X22: =COUNTIF('NOV DUMP'!C:C,'PARTNERS SUMMARY'!$B22) -> 0 | Y22: =COUNTIFS('NOV DUMP'!$C:$C,'PARTNERS SUMMARY'!$B22,'NOV DUMP'!$S:$S,"Prospect") -> 0 | Z22: =COUNTIFS('NOV DUMP'!$C:$C,'PARTNERS SUMMARY'!$B22,'NOV DUMP'!$S:$S,"Confirmed") -> 0 | AA22: =COUNTIFS('NOV DUMP'!$C:$C,'PARTNERS SUMMARY'!$B22,'NOV DUMP'!$S:$S,"Rejected") -> 0 | AB22: =COUNTIFS('NOV DUMP'!$C:$C,'PARTNERS SUMMARY'!$B22,'NOV DUMP'!$S:$S,"Unreachable") -> 0 | AC22: =COUNTIFS('NOV DUMP'!$C:$C,'PARTNERS SUMMARY'!$B22,'NOV DUMP'!$S:$S,"Postponed(Update Y)") -> 0 | AD22: =SUM(CQ22:DT22) -> 0 | AE22: =COUNTIFS('ACTIVATED LEADS '!$H:$H,'PARTNERS SUMMARY'!$B22,'ACTIVATED LEADS '!$K:$K,'PARTNERS SUMMARY'!$AE$2,'ACTIVATED LEADS '!$C:$C,"16") -> 0 | AF22: =IFERROR(AD22/X22,0) -> 0 | AH22: =COUNTIFS('ACTIVATED LEADS '!$H:$H,$B22,'ACTIVATED LEADS '!$D:$D,'PARTNERS SUMMARY'!AH$3) -> 0 | AI22: =COUNTIFS('ACTIVATED LEADS '!$H:$H,$B22,'ACTIVATED LEADS '!$D:$D,'PARTNERS SUMMARY'!AI$3) -> 0 | AJ22: =COUNTIFS('ACTIVATED LEADS '!$H:$H,$B22,'ACTIVATED LEADS '!$D:$D,'PARTNERS SUMMARY'!AJ$3) -> 0 | AK22: =COUNTIFS('ACTIVATED LEADS '!$H:$H,$B22,'ACTIVATED LEADS '!$D:$D,'PARTNERS SUMMARY'!AK$3) -> 0 | AL22: =COUNTIFS('ACTIVATED LEADS '!$H:$H,$B22,'ACTIVATED LEADS '!$D:$D,'PARTNERS SUMMARY'!AL$3) -> 0 | AM22: =COUNTIFS('ACTIVATED LEADS '!$H:$H,$B22,'ACTIVATED LEADS '!$D:$D,'PARTNERS SUMMARY'!AM$3) -> 0 | AN22: =COUNTIFS('ACTIVATED LEADS '!$H:$H,$B22,'ACTIVATED LEADS '!$D:$D,'PARTNERS SUMMARY'!AN$3) -> 0 | AO22: =COUNTIFS('ACTIVATED LEADS '!$H:$H,$B22,'ACTIVATED LEADS '!$D:$D,'PARTNERS SUMMARY'!AO$3) -> 0 | ... DO22: =COUNTIFS('ACTIVATED LEADS '!$H:$H,$B22,'ACTIVATED LEADS '!$D:$D,'PARTNERS SUMMARY'!DO$3) -> 0
A23: Damaris Mainga | B23: Ramitech Networks Ltd | C23: 105460674 | D23: Benson@gmail.com | E23: TRM | F23: Nairobi | G23: =COUNTIF('SEPT DUMP '!$C:$C,'PARTNERS SUMMARY'!$B23) -> 1 | H23: =COUNTIFS('SEPT DUMP '!$C:$C,'PARTNERS SUMMARY'!$B23,'SEPT DUMP '!$O:$O,"Confirmed") -> 1 | I23: =COUNTIFS('SEPT DUMP '!$C:$C,'PARTNERS SUMMARY'!$B23,'SEPT DUMP '!$O:$O,"Rejected") -> 0 | J23: =COUNTIFS('SEPT DUMP '!$C:$C,'PARTNERS SUMMARY'!$B23,'SEPT DUMP '!$O:$O,"Unreachable") -> 0 | K23: =COUNTIFS('SEPT DUMP '!$C:$C,'PARTNERS SUMMARY'!$B23,'SEPT DUMP '!$O:$O,"Postponed(Update Y)") -> 0 | L23: =SUM(AH23:BK23) -> 0 | M23: =IFERROR(L23/G23,0) -> 0 | O23: =COUNTIF('OCT DUMP'!$D:$D,'PARTNERS SUMMARY'!$B23) -> 0 | P23: =COUNTIFS('OCT DUMP'!$D:$D,'PARTNERS SUMMARY'!$B23,'OCT DUMP'!Q:Q,"Prospect") -> 0 | Q23: =COUNTIFS('OCT DUMP'!$D:$D,'PARTNERS SUMMARY'!$B23,'OCT DUMP'!$Q:$Q,"Confirmed") -> 0 | R23: =COUNTIFS('OCT DUMP'!$D:$D,'PARTNERS SUMMARY'!$B23,'OCT DUMP'!$Q:$Q,"Rejected") -> 0 | S23: =COUNTIFS('OCT DUMP'!$D:$D,'PARTNERS SUMMARY'!$B23,'OCT DUMP'!$Q:$Q,"Unreachable") -> 0 | T23: =COUNTIFS('OCT DUMP'!$D:$D,'PARTNERS SUMMARY'!$B23,'OCT DUMP'!$Q:$Q,"Postponed(Update Y)") -> 0 | U23: =SUM(BL23:CP23) -> 1 | V23: =IFERROR(U23/O23,0) -> 0 | X23: =COUNTIF('NOV DUMP'!C:C,'PARTNERS SUMMARY'!$B23) -> 1 | Y23: =COUNTIFS('NOV DUMP'!$C:$C,'PARTNERS SUMMARY'!$B23,'NOV DUMP'!$S:$S,"Prospect") -> 0 | Z23: =COUNTIFS('NOV DUMP'!$C:$C,'PARTNERS SUMMARY'!$B23,'NOV DUMP'!$S:$S,"Confirmed") -> 0 | AA23: =COUNTIFS('NOV DUMP'!$C:$C,'PARTNERS SUMMARY'!$B23,'NOV DUMP'!$S:$S,"Rejected") -> 0 | AB23: =COUNTIFS('NOV DUMP'!$C:$C,'PARTNERS SUMMARY'!$B23,'NOV DUMP'!$S:$S,"Unreachable") -> 0 | AC23: =COUNTIFS('NOV DUMP'!$C:$C,'PARTNERS SUMMARY'!$B23,'NOV DUMP'!$S:$S,"Postponed(Update Y)") -> 0 | AD23: =SUM(CQ23:DT23) -> 0 | AE23: =COUNTIFS('ACTIVATED LEADS '!$H:$H,'PARTNERS SUMMARY'!$B23,'ACTIVATED LEADS '!$K:$K,'PARTNERS SUMMARY'!$AE$2,'ACTIVATED LEADS '!$C:$C,"16") -> 0 | AF23: =IFERROR(AD23/X23,0) -> 0 | AH23: =COUNTIFS('ACTIVATED LEADS '!$H:$H,$B23,'ACTIVATED LEADS '!$D:$D,'PARTNERS SUMMARY'!AH$3) -> 0 | AI23: =COUNTIFS('ACTIVATED LEADS '!$H:$H,$B23,'ACTIVATED LEADS '!$D:$D,'PARTNERS SUMMARY'!AI$3) -> 0 | AJ23: =COUNTIFS('ACTIVATED LEADS '!$H:$H,$B23,'ACTIVATED LEADS '!$D:$D,'PARTNERS SUMMARY'!AJ$3) -> 0 | AK23: =COUNTIFS('ACTIVATED LEADS '!$H:$H,$B23,'ACTIVATED LEADS '!$D:$D,'PARTNERS SUMMARY'!AK$3) -> 0 | AL23: =COUNTIFS('ACTIVATED LEADS '!$H:$H,$B23,'ACTIVATED LEADS '!$D:$D,'PARTNERS SUMMARY'!AL$3) -> 0 | AM23: =COUNTIFS('ACTIVATED LEADS '!$H:$H,$B23,'ACTIVATED LEADS '!$D:$D,'PARTNERS SUMMARY'!AM$3) -> 0 | AN23: =COUNTIFS('ACTIVATED LEADS '!$H:$H,$B23,'ACTIVATED LEADS '!$D:$D,'PARTNERS SUMMARY'!AN$3) -> 0 | AO23: =COUNTIFS('ACTIVATED LEADS '!$H:$H,$B23,'ACTIVATED LEADS '!$D:$D,'PARTNERS SUMMARY'!AO$3) -> 0 | ... DO23: =COUNTIFS('ACTIVATED LEADS '!$H:$H,$B23,'ACTIVATED LEADS '!$D:$D,'PARTNERS SUMMARY'!DO$3) -> 0
